Workbook

Sheet 시작하기
B2: 제이슨의 머니쇼 가계부 2026
B3: 흔들리지 않는 돈 관리는, 내 돈이 어디로 가는지 아는 것에서 시작합니다.
B6: STEP 1 · 설정 | C6: ‘설정’ 시트에서 수입원·고정지출·지출 카테고리·저축 목표의 이름과 금액을 적어요. 한 번만 적으면 12개월 시트에 자동 반영됩니다.
B7: STEP 2 · 매달 기록 | C7: 각 ‘월’ 시트의 ‘변동지출 기록’에 날짜·분류·금액만 적으면 돼요. 분류 칸을 누르면 목록에서 고를 수 있어요.
B8: STEP 3 · 한눈에 보기 | C8: ‘이번 달 한눈에’·‘카테고리별 예산 vs 사용’·차트가 자동으로 계산됩니다. ‘연간 대시보드’에서 1년 흐름을 봅니다.
B9: 색깔 안내 | C9: 민트색 칸은 자동 계산되는 칸이에요. 직접 지우거나 고치지 마세요. 흰 칸에만 입력하면 됩니다.
B10: 숫자 단위 | C10: 모든 금액은 원(₩) 단위입니다. 숫자만 입력하면 자동으로 ₩ 표시가 붙어요.
B11: 내 것으로 쓰기 | C11: 이 파일은 ‘사본 만들기’로 받은 내 구글 시트예요. 항목 이름·카테고리·행 개수 모두 자유롭게 바꿔도 됩니다.
B12: 색 구분 | C12: ■ 민트색 = 자동 계산 칸 (건드리지 마세요) · □ 흰색 = 직접 입력 칸
B14: 구성 (탭) | C14: 시작하기 · 설정 · 연간 대시보드 · 1~12월 · 카테고리 개요 · 저축 목표 · 순자산 · 고정지출·구독
B16: 안내 · 면책 | C16: 이 가계부는 가계 재무 정리를 돕는 교육용 도구이며, 개별 투자자문이 아닙니다. 수익·원금을 보장하지 않으며 최종 판단과 책임은 본인에게 있습니다. 제작: 제이슨의 머니쇼.

Sheet 설정
B2: 설정 · 내 항목과 금액 정하기
B3: 흰 칸에 내 상황에 맞는 이름과 금액을 적어주세요. 모든 달 시트에 자동으로 반영됩니다.
B4: ① 수입원
B5: 항목 | C5: 월 예상
B6: 월급 (본업) | C6: 3500000
B7: 부수입 / 사이드잡 | C7: 400000
B8: 상여 / 보너스 | C8: 0
B9: 이자 / 배당 | C9: 50000
B10: 용돈 / 기타 | C10: 0
B14: ② 고정지출
B15: 항목 | C15: 월 금액 | D15: 결제일
B16: 월세 / 주택대출 상환 | C16: 600000 | D16: 25일
B17: 관리비 | C17: 150000 | D17: 30일
B18: 통신비 (휴대폰·인터넷) | C18: 88000 | D18: 15일
B19: 보험료 | C19: 120000 | D19: 5일
B20: 구독 서비스 | C20: 29000 | D20: 10일
B21: 교통 정기권 | C21: 62000 | D21: 1일
B22: 적금 | C22: 300000 | D22: 25일
B23: 청약저축 | C23: 100000 | D23: 25일
B24: 대출 이자 | C24: 180000 | D24: 25일
B25: 공과금 (전기·가스·수도) | C25: 140000 | D25: 말일
B29: ③ 지출 카테고리 (변동)
B30: 항목 | C30: 월 예산
B31: 식비 (장보기) | C31: 350000
B32: 외식 / 카페 | C32: 200000
B33: 생활용품 | C33: 80000
B34: 교통 / 차량 | C34: 120000
B35: 의료 / 건강 | C35: 60000
B36: 의류 / 미용 | C36: 100000
B37: 교육 / 자기계발 | C37: 80000
B38: 문화 / 여가 | C38: 80000
B39: 경조사 / 선물 | C39: 100000
B40: 자녀 / 육아 | C40: 0
B41: 반려동물 | C41: 0
B42: 여행 | C42: 100000
... B45: 기타 | C45: 80000
B47: ④ 저축·투자 목표 (월 정기)
B48: 항목 | C48: 월 목표
B49: 비상금 | C49: 150000
B50: 청약 / 내집마련 | C50: 100000
...

Sheet 연간 대시보드
B2: 연간 대시보드 · 2026
B3: 각 달 시트에 기록하면 아래 표와 그래프가 자동으로 채워집니다.
B5: 연 총수입 | D5: 연 총지출 | F5: 연 저축·투자 | H5: 평균 저축률 | J5: 최근 순자산
B6: =SUM(C8:C19) -> 3950000 | D6: =SUM(D8:D19) -> 2478000 | F6: =SUM(E8:E19) -> 1100000 | H6: =IFERROR((SUM(C8:C19)-SUM(D8:D19))/SUM(C8:C19),0) -> 0.37265823 | J6: =순자산!C3 -> 99700000
B7: 월 | C7: 수입 | D7: 지출 | E7: 저축·투자 | F7: 남은 돈 | G7: 저축률
B8: 1월 | C8: ='1월'!D4 -> 3950000 | D8: ='1월'!D5 -> 2478000 | E8: ='1월'!D6 -> 1100000 | F8: ='1월'!D7 -> 372000 | G8: ='1월'!D8 -> 0.37265823
B9: 2월 | C9: ='2월'!D4 -> 0 | D9: ='2월'!D5 -> 0 | E9: ='2월'!D6 -> 0 | F9: ='2월'!D7 -> 0 | G9: ='2월'!D8 -> 0
B10: 3월 | C10: ='3월'!D4 -> 0 | D10: ='3월'!D5 -> 0 | E10: ='3월'!D6 -> 0 | F10: ='3월'!D7 -> 0 | G10: ='3월'!D8 -> 0
B11: 4월 | C11: ='4월'!D4 -> 0 | D11: ='4월'!D5 -> 0 | E11: ='4월'!D6 -> 0 | F11: ='4월'!D7 -> 0 | G11: ='4월'!D8 -> 0
B12: 5월 | C12: ='5월'!D4 -> 0 | D12: ='5월'!D5 -> 0 | E12: ='5월'!D6 -> 0 | F12: ='5월'!D7 -> 0 | G12: ='5월'!D8 -> 0
B13: 6월 | C13: ='6월'!D4 -> 0 | D13: ='6월'!D5 -> 0 | E13: ='6월'!D6 -> 0 | F13: ='6월'!D7 -> 0 | G13: ='6월'!D8 -> 0
B14: 7월 | C14: ='7월'!D4 -> 0 | D14: ='7월'!D5 -> 0 | E14: ='7월'!D6 -> 0 | F14: ='7월'!D7 -> 0 | G14: ='7월'!D8 -> 0
B15: 8월 | C15: ='8월'!D4 -> 0 | D15: ='8월'!D5 -> 0 | E15: ='8월'!D6 -> 0 | F15: ='8월'!D7 -> 0 | G15: ='8월'!D8 -> 0
B16: 9월 | C16: ='9월'!D4 -> 0 | D16: ='9월'!D5 -> 0 | E16: ='9월'!D6 -> 0 | F16: ='9월'!D7 -> 0 | G16: ='9월'!D8 -> 0
B17: 10월 | C17: ='10월'!D4 -> 0 | D17: ='10월'!D5 -> 0 | E17: ='10월'!D6 -> 0 | F17: ='10월'!D7 -> 0 | G17: ='10월'!D8 -> 0
B18: 11월 | C18: ='11월'!D4 -> 0 | D18: ='11월'!D5 -> 0 | E18: ='11월'!D6 -> 0 | F18: ='11월'!D7 -> 0 | G18: ='11월'!D8 -> 0
B19: 12월 | C19: ='12월'!D4 -> 0 | D19: ='12월'!D5 -> 0 | E19: ='12월'!D6 -> 0 | F19: ='12월'!D7 -> 0 | G19: ='12월'!D8 -> 0
B20: 합계 | C20: =SUM(C8:C19) -> 3950000 | D20: =SUM(D8:D19) -> 2478000 | E20: =SUM(E8:E19) -> 1100000 | F20: =SUM(F8:F19) -> 372000 | G20: =IFERROR((C20-D20)/C20,0) -> 0.37265823
B21: 월평균 | C21: =AVERAGE(C8:C19) -> 329166.67 | D21: =AVERAGE(D8:D19) -> 206500 | E21: =AVERAGE(E8:E19) -> 91666.667 | F21: =AVERAGE(F8:F19) -> 31000 | G21: =IFERROR(AVERAGE(G8:G19),0) -> 0.031054852
M43: 연간 지출·저축 구성
M44: 고정지출 | N44: ='1월'!E35+'2월'!E35+'3월'!E35+'4월'!E35+'5월'!E35+'6월'!E35+'7월'!E35+'8월'!E35+'9월'!E35+'10월'!E35+'11월'!E35+'12월'!E35 -> 1769000
M45: 변동지출 | N45: =D20-N44 -> 709000
M46: 저축·투자 | N46: =E20 -> 1100000

Sheet 1월
B1: 1월 가계부 | L1: 제이슨의 머니쇼 · 2026 | V1: 월 지출(전체) 차트 데이터
V2: =IF(L5="","",L5) -> 식비 (장보기) | W2: =N5 -> 183000
B3: 이번 달 한눈에 | G3: 변동지출 기록 | L3: 카테고리별 예산 vs 사용 | R3: 차트 데이터 | V3: =IF(L6="","",L6) -> 외식 / 카페 | W3: =N6 -> 96000
B4: 총수입 | D4: =D19 -> 3950000 | G4: 날짜 | H4: 분류 | I4: 내용 | J4: 금액 | L4: 분류 | M4: 예산 | N4: 사용 | O4: 달성 | P4: 진행 | R4: 구분 | S4: 예산 | T4: 실제 | V4: =IF(L7="","",L7) -> 생활용품 | W4: =N7 -> 23000
B5: 총지출 | D5: =E35+J55 -> 2478000 | G5: 2 | H5: 식비 (장보기) | I5: 이마트 장보기 | J5: 68000 | L5: =IF(설정!$B$31="","",설정!$B$31) -> 식비 (장보기) | M5: =IF(설정!$C$31="","",설정!$C$31) -> 350000 | N5: =SUMIF($H$5:$H$54,L5,$J$5:$J$54) -> 183000 | O5: =IFERROR(N5/M5,0) -> 0.52285714 | P5: =IF(M5="","",REPT("■",MIN(10,ROUND(O5*10,0)))&REPT("□",10-MIN(10,ROUND(O5*10,0)))) -> ■■■■■□□□□□ | R5: 수입 | S5: =C19 -> 3950000 | T5: =D19 -> 3950000 | V5: =IF(L8="","",L8) -> 교통 / 차량 | W5: =N8 -> 70000
B6: 저축·투자 | D6: =D45 -> 1100000 | G6: 3 | H6: 외식 / 카페 | I6: 점심 약속 | J6: 32000 | L6: =IF(설정!$B$32="","",설정!$B$32) -> 외식 / 카페 | M6: =IF(설정!$C$32="","",설정!$C$32) -> 200000 | N6: =SUMIF($H$5:$H$54,L6,$J$5:$J$54) -> 96000 | O6: =IFERROR(N6/M6,0) -> 0.48 | P6: =IF(M6="","",REPT("■",MIN(10,ROUND(O6*10,0)))&REPT("□",10-MIN(10,ROUND(O6*10,0)))) -> ■■■■■□□□□□ | R6: 지출 | S6: =C35+M20 -> 3179000 | T6: =E35+J55 -> 2478000 | V6: =IF(L9="","",L9) -> 의료 / 건강 | W6: =N9 -> 12000
B7: 남은 돈 | D7: =D4-D5-D6 -> 372000 | G7: 5 | H7: 교통 / 차량 | I7: 주유 | J7: 70000 | L7: =IF(설정!$B$33="","",설정!$B$33) -> 생활용품 | M7: =IF(설정!$C$33="","",설정!$C$33) -> 80000 | N7: =SUMIF($H$5:$H$54,L7,$J$5:$J$54) -> 23000 | O7: =IFERROR(N7/M7,0) -> 0.2875 | P7: =IF(M7="","",REPT("■",MIN(10,ROUND(O7*10,0)))&REPT("□",10-MIN(10,ROUND(O7*10,0)))) -> ■■■□□□□□□□ | R7: 저축 | S7: =C45 -> 1100000 | T7: =D45 -> 1100000 | V7: =IF(L10="","",L10) -> 의류 / 미용 | W7: =N10 -> 45000
B8: 저축률 | D8: =IFERROR((D4-D5)/D4,0) -> 0.37265823 | G8: 6 | H8: 문화 / 여가 | I8: 영화 관람 | J8: 28000 | L8: =IF(설정!$B$34="","",설정!$B$34) -> 교통 / 차량 | M8: =IF(설정!$C$34="","",설정!$C$34) -> 120000 | N8: =SUMIF($H$5:$H$54,L8,$J$5:$J$54) -> 70000 | O8: =IFERROR(N8/M8,0) -> 0.58333333 | P8: =IF(M8="","",REPT("■",MIN(10,ROUND(O8*10,0)))&REPT("□",10-MIN(10,ROUND(O8*10,0)))) -> ■■■■■■□□□□ | V8: =IF(L11="","",L11) -> 교육 / 자기계발 | W8: =N11 -> 39000
G9: 8 | H9: 식비 (장보기) | I9: 동네 마트 | J9: 54000 | L9: =IF(설정!$B$35="","",설정!$B$35) -> 의료 / 건강 | M9: =IF(설정!$C$35="","",설정!$C$35) -> 60000 | N9: =SUMIF($H$5:$H$54,L9,$J$5:$J$54) -> 12000 | O9: =IFERROR(N9/M9,0) -> 0.2 | P9: =IF(M9="","",REPT("■",MIN(10,ROUND(O9*10,0)))&REPT("□",10-MIN(10,ROUND(O9*10,0)))) -> ■■□□□□□□□□ | R9: 고정지출 | S9: =E35 -> 1769000 | V9: =IF(L12="","",L12) -> 문화 / 여가 | W9: =N12 -> 28000
B10: 수입 | G10: 9 | H10: 의류 / 미용 | I10: 미용실 | J10: 45000 | L10: =IF(설정!$B$36="","",설정!$B$36) -> 의류 / 미용 | M10: =IF(설정!$C$36="","",설정!$C$36) -> 100000 | N10: =SUMIF($H$5:$H$54,L10,$J$5:$J$54) -> 45000 | O10: =IFERROR(N10/M10,0) -> 0.45 | P10: =IF(M10="","",REPT("■",MIN(10,ROUND(O10*10,0)))&REPT("□",10-MIN(10,ROUND(O10*10,0)))) -> ■■■■■□□□□□ | R10: 변동지출 | S10: =J55 -> 709000 | V10: =IF(L13="","",L13) -> 경조사 / 선물 | W10: =N13 -> 50000
B11: 항목 | C11: 예상 | D11: 실제 | E11: 차이 | G11: 11 | H11: 외식 / 카페 | I11: 주말 카페 | J11: 18000 | L11: =IF(설정!$B$37="","",설정!$B$37) -> 교육 / 자기계발 | M11: =IF(설정!$C$37="","",설정!$C$37) -> 80000 | N11: =SUMIF($H$5:$H$54,L11,$J$5:$J$54) -> 39000 | O11: =IFERROR(N11/M11,0) -> 0.4875 | P11: =IF(M11="","",REPT("■",MIN(10,ROUND(O11*10,0)))&REPT("□",10-MIN(10,ROUND(O11*10,0)))) -> ■■■■■□□□□□ | V11: =IF(L14="","",L14) -> 자녀 / 육아 | W11: =N14 -> 0
B12: =IF(설정!$B$6="","",설정!$B$6) -> 월급 (본업) | C12: =IF(설정!$C$6="","",설정!$C$6) -> 3500000 | D12: 3500000 | E12: =IF(D12="","",D12-C12) -> 0 | G12: 13 | H12: 생활용품 | I12: 다이소 | J12: 23000 | L12: =IF(설정!$B$38="","",설정!$B$38) -> 문화 / 여가 | M12: =IF(설정!$C$38="","",설정!$C$38) -> 80000 | N12: =SUMIF($H$5:$H$54,L12,$J$5:$J$54) -> 28000 | O12: =IFERROR(N12/M12,0) -> 0.35 | P12: =IF(M12="","",REPT("■",MIN(10,ROUND(O12*10,0)))&REPT("□",10-MIN(10,ROUND(O12*10,0)))) -> ■■■■□□□□□□ | V12: =IF(L15="","",L15) -> 반려동물 | W12: =N15 -> 0
B13: =IF(설정!$B$7="","",설정!$B$7) -> 부수입 / 사이드잡 | C13: =IF(설정!$C$7="","",설정!$C$7) -> 400000 | D13: 400000 | E13: =IF(D13="","",D13-C13) -> 0 | G13: 15 | H13: 의료 / 건강 | I13: 약국 | J13: 12000 | L13: =IF(설정!$B$39="","",설정!$B$39) -> 경조사 / 선물 | M13: =IF(설정!$C$39="","",설정!$C$39) -> 100000 | N13: =SUMIF($H$5:$H$54,L13,$J$5:$J$54) -> 50000 | O13: =IFERROR(N13/M13,0) -> 0.5 | P13: =IF(M13="","",REPT("■",MIN(10,ROUND(O13*10,0)))&REPT("□",10-MIN(10,ROUND(O13*10,0)))) -> ■■■■■□□□□□ | V13: =IF(L16="","",L16) -> 여행 | W13: =N16 -> 120000
B14: =IF(설정!$B$8="","",설정!$B$8) -> 상여 / 보너스 | C14: =IF(설정!$C$8="","",설정!$C$8) -> 0 | D14: 0 | E14: =IF(D14="","",D14-C14) -> 0 | G14: 17 | H14: 경조사 / 선물 | I14: 친구 생일선물 | J14: 50000 | L14: =IF(설정!$B$40="","",설정!$B$40) -> 자녀 / 육아 | M14: =IF(설정!$C$40="","",설정!$C$40) -> 0 | N14: =SUMIF($H$5:$H$54,L14,$J$5:$J$54) -> 0 | O14: =IFERROR(N14/M14,0) -> 0 | P14: =IF(M14="","",REPT("■",MIN(10,ROUND(O14*10,0)))&REPT("□",10-MIN(10,ROUND(O14*10,0)))) -> □□□□□□□□□□ | V14: =IF(L17="","",L17) -> 통신 / 디지털 | W14: =N17 -> 13000
B15: =IF(설정!$B$9="","",설정!$B$9) -> 이자 / 배당 | C15: =IF(설정!$C$9="","",설정!$C$9) -> 50000 | D15: 50000 | E15: =IF(D15="","",D15-C15) -> 0 | G15: 19 | H15: 여행 | I15: 주말 여행 숙박 | J15: 120000 | L15: =IF(설정!$B$41="","",설정!$B$41) -> 반려동물 | M15: =IF(설정!$C$41="","",설정!$C$41) -> 0 | N15: =SUMIF($H$5:$H$54,L15,$J$5:$J$54) -> 0 | O15: =IFERROR(N15/M15,0) -> 0 | P15: =IF(M15="","",REPT("■",MIN(10,ROUND(O15*10,0)))&REPT("□",10-MIN(10,ROUND(O15*10,0)))) -> □□□□□□□□□□ | V15: =IF(L18="","",L18) -> 기부 / 후원 | W15: =N18 -> 30000
B16: =IF(설정!$B$10="","",설정!$B$10) -> 용돈 / 기타 | C16: =IF(설정!$C$10="","",설정!$C$10) -> 0 | D16: 0 | E16: =IF(D16="","",D16-C16) -> 0 | G16: 21 | H16: 외식 / 카페 | I16: 저녁 외식 | J16: 46000 | L16: =IF(설정!$B$42="","",설정!$B$42) -> 여행 | M16: =IF(설정!$C$42="","",설정!$C$42) -> 100000 | N16: =SUMIF($H$5:$H$54,L16,$J$5:$J$54) -> 120000 | O16: =IFERROR(N16/M16,0) -> 1.2 | P16: =IF(M16="","",REPT("■",MIN(10,ROUND(O16*10,0)))&REPT("□",10-MIN(10,ROUND(O16*10,0)))) -> ■■■■■■■■■■ | V16: =IF(L19="","",L19) -> 기타 | W16: =N19 -> 0
B17: =IF(설정!$B$11="","",설정!$B$11) | C17: =IF(설정!$C$11="","",설정!$C$11) | E17: =IF(D17="","",D17-C17) | G17: 23 | H17: 식비 (장보기) | I17: 장보기 | J17: 61000 | L17: =IF(설정!$B$43="","",설정!$B$43) -> 통신 / 디지털 | M17: =IF(설정!$C$43="","",설정!$C$43) -> 30000 | N17: =SUMIF($H$5:$H$54,L17,$J$5:$J$54) -> 13000 | O17: =IFERROR(N17/M17,0) -> 0.43333333 | P17: =IF(M17="","",REPT("■",MIN(10,ROUND(O17*10,0)))&REPT("□",10-MIN(10,ROUND(O17*10,0)))) -> ■■■■□□□□□□ | V17: =IF(B23="","",B23) -> 월세 / 주택대출 상환 | W17: =E23 -> 600000
B18: =IF(설정!$B$12="","",설정!$B$12) | C18: =IF(설정!$C$12="","",설정!$C$12) | E18: =IF(D18="","",D18-C18) | G18: 25 | H18: 교육 / 자기계발 | I18: 온라인 강의 | J18: 39000 | L18: =IF(설정!$B$44="","",설정!$B$44) -> 기부 / 후원 | M18: =IF(설정!$C$44="","",설정!$C$44) -> 30000 | N18: =SUMIF($H$5:$H$54,L18,$J$5:$J$54) -> 30000 | O18: =IFERROR(N18/M18,0) -> 1 | P18: =IF(M18="","",REPT("■",MIN(10,ROUND(O18*10,0)))&REPT("□",10-MIN(10,ROUND(O18*10,0)))) -> ■■■■■■■■■■ | V18: =IF(B24="","",B24) -> 관리비 | W18: =E24 -> 150000
B19: 합계 | C19: =SUM(C12:C18) -> 3950000 | D19: =SUM(D12:D18) -> 3950000 | E19: =D19-C19 -> 0 | G19: 27 | H19: 기부 / 후원 | I19: 정기 후원 | J19: 30000 | L19: =IF(설정!$B$45="","",설정!$B$45) -> 기타 | M19: =IF(설정!$C$45="","",설정!$C$45) -> 80000 | N19: =SUMIF($H$5:$H$54,L19,$J$5:$J$54) -> 0 | O19: =IFERROR(N19/M19,0) -> 0 | P19: =IF(M19="","",REPT("■",MIN(10,ROUND(O19*10,0)))&REPT("□",10-MIN(10,ROUND(O19*10,0)))) -> □□□□□□□□□□ | V19: =IF(B25="","",B25) -> 통신비 (휴대폰·인터넷) | W19: =E25 -> 88000
G20: 29 | H20: 통신 / 디지털 | I20: 앱 구독 결제 | J20: 13000 | L20: 합계 | M20: =SUM(M5:M19) -> 1410000 | N20: =SUM(N5:N19) -> 709000 | V20: =IF(B26="","",B26) -> 보험료 | W20: =E26 -> 120000
B21: 고정지출 | V21: =IF(B27="","",B27) -> 구독 서비스 | W21: =E27 -> 29000
B22: 항목 | C22: 예산 | D22: 결제일 | E22: 실제 | V22: =IF(B28="","",B28) -> 교통 정기권 | W22: =E28 -> 62000
B23: =IF(설정!$B$16="","",설정!$B$16) -> 월세 / 주택대출 상환 | C23: =IF(설정!$C$16="","",설정!$C$16) -> 600000 | D23: =IF(설정!$D$16="","",설정!$D$16) -> 25일 | E23: 600000 | V23: =IF(B29="","",B29) -> 적금 | W23: =E29 -> 300000
B24: =IF(설정!$B$17="","",설정!$B$17) -> 관리비 | C24: =IF(설정!$C$17="","",설정!$C$17) -> 150000 | D24: =IF(설정!$D$17="","",설정!$D$17) -> 30일 | E24: 150000 | V24: =IF(B30="","",B30) -> 청약저축 | W24: =E30 -> 100000
B25: =IF(설정!$B$18="","",설정!$B$18) -> 통신비 (휴대폰·인터넷) | C25: =IF(설정!$C$18="","",설정!$C$18) -> 88000 | D25: =IF(설정!$D$18="","",설정!$D$18) -> 15일 | E25: 88000 | V25: =IF(B31="","",B31) -> 대출 이자 | W25: =E31 -> 180000
B26: =IF(설정!$B$19="","",설정!$B$19) -> 보험료 | C26: =IF(설정!$C$19="","",설정!$C$19) -> 120000 | D26: =IF(설정!$D$19="","",설정!$D$19) -> 5일 | E26: 120000 | V26: =IF(B32="","",B32) -> 공과금 (전기·가스·수도) | W26: =E32 -> 140000
B27: =IF(설정!$B$20="","",설정!$B$20) -> 구독 서비스 | C27: =IF(설정!$C$20="","",설정!$C$20) -> 29000 | D27: =IF(설정!$D$20="","",설정!$D$20) -> 10일 | E27: 29000 | V27: =IF(B33="","",B33) | W27: =E33 -> 0
B28: =IF(설정!$B$21="","",설정!$B$21) -> 교통 정기권 | C28: =IF(설정!$C$21="","",설정!$C$21) -> 62000 | D28: =IF(설정!$D$21="","",설정!$D$21) -> 1일 | E28: 62000 | V28: =IF(B34="","",B34) | W28: =E34 -> 0
B29: =IF(설정!$B$22="","",설정!$B$22) -> 적금 | C29: =IF(설정!$C$22="","",설정!$C$22) -> 300000 | D29: =IF(설정!$D$22="","",설정!$D$22) -> 25일 | E29: 300000
B30: =IF(설정!$B$23="","",설정!$B$23) -> 청약저축 | C30: =IF(설정!$C$23="","",설정!$C$23) -> 100000 | D30: =IF(설정!$D$23="","",설정!$D$23) -> 25일 | E30: 100000
B31: =IF(설정!$B$24="","",설정!$B$24) -> 대출 이자 | C31: =IF(설정!$C$24="","",설정!$C$24) -> 180000 | D31: =IF(설정!$D$24="","",설정!$D$24) -> 25일 | E31: 180000
B32: =IF(설정!$B$25="","",설정!$B$25) -> 공과금 (전기·가스·수도) | C32: =IF(설정!$C$25="","",설정!$C$25) -> 140000 | D32: =IF(설정!$D$25="","",설정!$D$25) -> 말일 | E32: 140000
B33: =IF(설정!$B$26="","",설정!$B$26) | C33: =IF(설정!$C$26="","",설정!$C$26) | D33: =IF(설정!$D$26="","",설정!$D$26)
B34: =IF(설정!$B$27="","",설정!$B$27) | C34: =IF(설정!$C$27="","",설정!$C$27) | D34: =IF(설정!$D$27="","",설정!$D$27)
B35: 합계 | C35: =SUM(C23:C34) -> 1769000 | E35: =SUM(E23:E34) -> 1769000
B37: 저축·투자
B38: 항목 | C38: 목표 | D38: 실제 | E38: 차이
B39: =IF(설정!$B$49="","",설정!$B$49) -> 비상금 | C39: =IF(설정!$C$49="","",설정!$C$49) -> 150000 | D39: 150000 | E39: =IF(D39="","",D39-C39) -> 0
B40: =IF(설정!$B$50="","",설정!$B$50) -> 청약 / 내집마련 | C40: =IF(설정!$C$50="","",설정!$C$50) -> 100000 | D40: 100000 | E40: =IF(D40="","",D40-C40) -> 0
B41: =IF(설정!$B$51="","",설정!$B$51) -> 투자 (ETF·주식) | C41: =IF(설정!$C$51="","",설정!$C$51) -> 400000 | D41: 400000 | E41: =IF(D41="","",D41-C41) -> 0
...

Sheet 2월
B1: 2월 가계부 | L1: 제이슨의 머니쇼 · 2026 | V1: 월 지출(전체) 차트 데이터
V2: =IF(L5="","",L5) -> 식비 (장보기) | W2: =N5 -> 0
B3: 이번 달 한눈에 | G3: 변동지출 기록 | L3: 카테고리별 예산 vs 사용 | R3: 차트 데이터 | V3: =IF(L6="","",L6) -> 외식 / 카페 | W3: =N6 -> 0
B4: 총수입 | D4: =D19 -> 0 | G4: 날짜 | H4: 분류 | I4: 내용 | J4: 금액 | L4: 분류 | M4: 예산 | N4: 사용 | O4: 달성 | P4: 진행 | R4: 구분 | S4: 예산 | T4: 실제 | V4: =IF(L7="","",L7) -> 생활용품 | W4: =N7 -> 0
B5: 총지출 | D5: =E35+J55 -> 0 | L5: =IF(설정!$B$31="","",설정!$B$31) -> 식비 (장보기) | M5: =IF(설정!$C$31="","",설정!$C$31) -> 350000 | N5: =SUMIF($H$5:$H$54,L5,$J$5:$J$54) -> 0 | O5: =IFERROR(N5/M5,0) -> 0 | P5: =IF(M5="","",REPT("■",MIN(10,ROUND(O5*10,0)))&REPT("□",10-MIN(10,ROUND(O5*10,0)))) -> □□□□□□□□□□ | R5: 수입 | S5: =C19 -> 3950000 | T5: =D19 -> 0 | V5: =IF(L8="","",L8) -> 교통 / 차량 | W5: =N8 -> 0
B6: 저축·투자 | D6: =D45 -> 0 | L6: =IF(설정!$B$32="","",설정!$B$32) -> 외식 / 카페 | M6: =IF(설정!$C$32="","",설정!$C$32) -> 200000 | N6: =SUMIF($H$5:$H$54,L6,$J$5:$J$54) -> 0 | O6: =IFERROR(N6/M6,0) -> 0 | P6: =IF(M6="","",REPT("■",MIN(10,ROUND(O6*10,0)))&REPT("□",10-MIN(10,ROUND(O6*10,0)))) -> □□□□□□□□□□ | R6: 지출 | S6: =C35+M20 -> 3179000 | T6: =E35+J55 -> 0 | V6: =IF(L9="","",L9) -> 의료 / 건강 | W6: =N9 -> 0
B7: 남은 돈 | D7: =D4-D5-D6 -> 0 | L7: =IF(설정!$B$33="","",설정!$B$33) -> 생활용품 | M7: =IF(설정!$C$33="","",설정!$C$33) -> 80000 | N7: =SUMIF($H$5:$H$54,L7,$J$5:$J$54) -> 0 | O7: =IFERROR(N7/M7,0) -> 0 | P7: =IF(M7="","",REPT("■",MIN(10,ROUND(O7*10,0)))&REPT("□",10-MIN(10,ROUND(O7*10,0)))) -> □□□□□□□□□□ | R7: 저축 | S7: =C45 -> 1100000 | T7: =D45 -> 0 | V7: =IF(L10="","",L10) -> 의류 / 미용 | W7: =N10 -> 0
B8: 저축률 | D8: =IFERROR((D4-D5)/D4,0) -> 0 | L8: =IF(설정!$B$34="","",설정!$B$34) -> 교통 / 차량 | M8: =IF(설정!$C$34="","",설정!$C$34) -> 120000 | N8: =SUMIF($H$5:$H$54,L8,$J$5:$J$54) -> 0 | O8: =IFERROR(N8/M8,0) -> 0 | P8: =IF(M8="","",REPT("■",MIN(10,ROUND(O8*10,0)))&REPT("□",10-MIN(10,ROUND(O8*10,0)))) -> □□□□□□□□□□ | V8: =IF(L11="","",L11) -> 교육 / 자기계발 | W8: =N11 -> 0
L9: =IF(설정!$B$35="","",설정!$B$35) -> 의료 / 건강 | M9: =IF(설정!$C$35="","",설정!$C$35) -> 60000 | N9: =SUMIF($H$5:$H$54,L9,$J$5:$J$54) -> 0 | O9: =IFERROR(N9/M9,0) -> 0 | P9: =IF(M9="","",REPT("■",MIN(10,ROUND(O9*10,0)))&REPT("□",10-MIN(10,ROUND(O9*10,0)))) -> □□□□□□□□□□ | R9: 고정지출 | S9: =E35 -> 0 | V9: =IF(L12="","",L12) -> 문화 / 여가 | W9: =N12 -> 0
B10: 수입 | L10: =IF(설정!$B$36="","",설정!$B$36) -> 의류 / 미용 | M10: =IF(설정!$C$36="","",설정!$C$36) -> 100000 | N10: =SUMIF($H$5:$H$54,L10,$J$5:$J$54) -> 0 | O10: =IFERROR(N10/M10,0) -> 0 | P10: =IF(M10="","",REPT("■",MIN(10,ROUND(O10*10,0)))&REPT("□",10-MIN(10,ROUND(O10*10,0)))) -> □□□□□□□□□□ | R10: 변동지출 | S10: =J55 -> 0 | V10: =IF(L13="","",L13) -> 경조사 / 선물 | W10: =N13 -> 0
B11: 항목 | C11: 예상 | D11: 실제 | E11: 차이 | L11: =IF(설정!$B$37="","",설정!$B$37) -> 교육 / 자기계발 | M11: =IF(설정!$C$37="","",설정!$C$37) -> 80000 | N11: =SUMIF($H$5:$H$54,L11,$J$5:$J$54) -> 0 | O11: =IFERROR(N11/M11,0) -> 0 | P11: =IF(M11="","",REPT("■",MIN(10,ROUND(O11*10,0)))&REPT("□",10-MIN(10,ROUND(O11*10,0)))) -> □□□□□□□□□□ | V11: =IF(L14="","",L14) -> 자녀 / 육아 | W11: =N14 -> 0
B12: =IF(설정!$B$6="","",설정!$B$6) -> 월급 (본업) | C12: =IF(설정!$C$6="","",설정!$C$6) -> 3500000 | E12: =IF(D12="","",D12-C12) | L12: =IF(설정!$B$38="","",설정!$B$38) -> 문화 / 여가 | M12: =IF(설정!$C$38="","",설정!$C$38) -> 80000 | N12: =SUMIF($H$5:$H$54,L12,$J$5:$J$54) -> 0 | O12: =IFERROR(N12/M12,0) -> 0 | P12: =IF(M12="","",REPT("■",MIN(10,ROUND(O12*10,0)))&REPT("□",10-MIN(10,ROUND(O12*10,0)))) -> □□□□□□□□□□ | V12: =IF(L15="","",L15) -> 반려동물 | W12: =N15 -> 0
B13: =IF(설정!$B$7="","",설정!$B$7) -> 부수입 / 사이드잡 | C13: =IF(설정!$C$7="","",설정!$C$7) -> 400000 | E13: =IF(D13="","",D13-C13) | L13: =IF(설정!$B$39="","",설정!$B$39) -> 경조사 / 선물 | M13: =IF(설정!$C$39="","",설정!$C$39) -> 100000 | N13: =SUMIF($H$5:$H$54,L13,$J$5:$J$54) -> 0 | O13: =IFERROR(N13/M13,0) -> 0 | P13: =IF(M13="","",REPT("■",MIN(10,ROUND(O13*10,0)))&REPT("□",10-MIN(10,ROUND(O13*10,0)))) -> □□□□□□□□□□ | V13: =IF(L16="","",L16) -> 여행 | W13: =N16 -> 0
B14: =IF(설정!$B$8="","",설정!$B$8) -> 상여 / 보너스 | C14: =IF(설정!$C$8="","",설정!$C$8) -> 0 | E14: =IF(D14="","",D14-C14) | L14: =IF(설정!$B$40="","",설정!$B$40) -> 자녀 / 육아 | M14: =IF(설정!$C$40="","",설정!$C$40) -> 0 | N14: =SUMIF($H$5:$H$54,L14,$J$5:$J$54) -> 0 | O14: =IFERROR(N14/M14,0) -> 0 | P14: =IF(M14="","",REPT("■",MIN(10,ROUND(O14*10,0)))&REPT("□",10-MIN(10,ROUND(O14*10,0)))) -> □□□□□□□□□□ | V14: =IF(L17="","",L17) -> 통신 / 디지털 | W14: =N17 -> 0
B15: =IF(설정!$B$9="","",설정!$B$9) -> 이자 / 배당 | C15: =IF(설정!$C$9="","",설정!$C$9) -> 50000 | E15: =IF(D15="","",D15-C15) | L15: =IF(설정!$B$41="","",설정!$B$41) -> 반려동물 | M15: =IF(설정!$C$41="","",설정!$C$41) -> 0 | N15: =SUMIF($H$5:$H$54,L15,$J$5:$J$54) -> 0 | O15: =IFERROR(N15/M15,0) -> 0 | P15: =IF(M15="","",REPT("■",MIN(10,ROUND(O15*10,0)))&REPT("□",10-MIN(10,ROUND(O15*10,0)))) -> □□□□□□□□□□ | V15: =IF(L18="","",L18) -> 기부 / 후원 | W15: =N18 -> 0
B16: =IF(설정!$B$10="","",설정!$B$10) -> 용돈 / 기타 | C16: =IF(설정!$C$10="","",설정!$C$10) -> 0 | E16: =IF(D16="","",D16-C16) | L16: =IF(설정!$B$42="","",설정!$B$42) -> 여행 | M16: =IF(설정!$C$42="","",설정!$C$42) -> 100000 | N16: =SUMIF($H$5:$H$54,L16,$J$5:$J$54) -> 0 | O16: =IFERROR(N16/M16,0) -> 0 | P16: =IF(M16="","",REPT("■",MIN(10,ROUND(O16*10,0)))&REPT("□",10-MIN(10,ROUND(O16*10,0)))) -> □□□□□□□□□□ | V16: =IF(L19="","",L19) -> 기타 | W16: =N19 -> 0
B17: =IF(설정!$B$11="","",설정!$B$11) | C17: =IF(설정!$C$11="","",설정!$C$11) | E17: =IF(D17="","",D17-C17) | L17: =IF(설정!$B$43="","",설정!$B$43) -> 통신 / 디지털 | M17: =IF(설정!$C$43="","",설정!$C$43) -> 30000 | N17: =SUMIF($H$5:$H$54,L17,$J$5:$J$54) -> 0 | O17: =IFERROR(N17/M17,0) -> 0 | P17: =IF(M17="","",REPT("■",MIN(10,ROUND(O17*10,0)))&REPT("□",10-MIN(10,ROUND(O17*10,0)))) -> □□□□□□□□□□ | V17: =IF(B23="","",B23) -> 월세 / 주택대출 상환 | W17: =E23 -> 0
B18: =IF(설정!$B$12="","",설정!$B$12) | C18: =IF(설정!$C$12="","",설정!$C$12) | E18: =IF(D18="","",D18-C18) | L18: =IF(설정!$B$44="","",설정!$B$44) -> 기부 / 후원 | M18: =IF(설정!$C$44="","",설정!$C$44) -> 30000 | N18: =SUMIF($H$5:$H$54,L18,$J$5:$J$54) -> 0 | O18: =IFERROR(N18/M18,0) -> 0 | P18: =IF(M18="","",REPT("■",MIN(10,ROUND(O18*10,0)))&REPT("□",10-MIN(10,ROUND(O18*10,0)))) -> □□□□□□□□□□ | V18: =IF(B24="","",B24) -> 관리비 | W18: =E24 -> 0
B19: 합계 | C19: =SUM(C12:C18) -> 3950000 | D19: =SUM(D12:D18) -> 0 | E19: =D19-C19 -> -3950000 | L19: =IF(설정!$B$45="","",설정!$B$45) -> 기타 | M19: =IF(설정!$C$45="","",설정!$C$45) -> 80000 | N19: =SUMIF($H$5:$H$54,L19,$J$5:$J$54) -> 0 | O19: =IFERROR(N19/M19,0) -> 0 | P19: =IF(M19="","",REPT("■",MIN(10,ROUND(O19*10,0)))&REPT("□",10-MIN(10,ROUND(O19*10,0)))) -> □□□□□□□□□□ | V19: =IF(B25="","",B25) -> 통신비 (휴대폰·인터넷) | W19: =E25 -> 0
L20: 합계 | M20: =SUM(M5:M19) -> 1410000 | N20: =SUM(N5:N19) -> 0 | V20: =IF(B26="","",B26) -> 보험료 | W20: =E26 -> 0
B21: 고정지출 | V21: =IF(B27="","",B27) -> 구독 서비스 | W21: =E27 -> 0
B22: 항목 | C22: 예산 | D22: 결제일 | E22: 실제 | V22: =IF(B28="","",B28) -> 교통 정기권 | W22: =E28 -> 0
B23: =IF(설정!$B$16="","",설정!$B$16) -> 월세 / 주택대출 상환 | C23: =IF(설정!$C$16="","",설정!$C$16) -> 600000 | D23: =IF(설정!$D$16="","",설정!$D$16) -> 25일 | V23: =IF(B29="","",B29) -> 적금 | W23: =E29 -> 0
B24: =IF(설정!$B$17="","",설정!$B$17) -> 관리비 | C24: =IF(설정!$C$17="","",설정!$C$17) -> 150000 | D24: =IF(설정!$D$17="","",설정!$D$17) -> 30일 | V24: =IF(B30="","",B30) -> 청약저축 | W24: =E30 -> 0
B25: =IF(설정!$B$18="","",설정!$B$18) -> 통신비 (휴대폰·인터넷) | C25: =IF(설정!$C$18="","",설정!$C$18) -> 88000 | D25: =IF(설정!$D$18="","",설정!$D$18) -> 15일 | V25: =IF(B31="","",B31) -> 대출 이자 | W25: =E31 -> 0
B26: =IF(설정!$B$19="","",설정!$B$19) -> 보험료 | C26: =IF(설정!$C$19="","",설정!$C$19) -> 120000 | D26: =IF(설정!$D$19="","",설정!$D$19) -> 5일 | V26: =IF(B32="","",B32) -> 공과금 (전기·가스·수도) | W26: =E32 -> 0
B27: =IF(설정!$B$20="","",설정!$B$20) -> 구독 서비스 | C27: =IF(설정!$C$20="","",설정!$C$20) -> 29000 | D27: =IF(설정!$D$20="","",설정!$D$20) -> 10일 | V27: =IF(B33="","",B33) | W27: =E33 -> 0
B28: =IF(설정!$B$21="","",설정!$B$21) -> 교통 정기권 | C28: =IF(설정!$C$21="","",설정!$C$21) -> 62000 | D28: =IF(설정!$D$21="","",설정!$D$21) -> 1일 | V28: =IF(B34="","",B34) | W28: =E34 -> 0
B29: =IF(설정!$B$22="","",설정!$B$22) -> 적금 | C29: =IF(설정!$C$22="","",설정!$C$22) -> 300000 | D29: =IF(설정!$D$22="","",설정!$D$22) -> 25일
B30: =IF(설정!$B$23="","",설정!$B$23) -> 청약저축 | C30: =IF(설정!$C$23="","",설정!$C$23) -> 100000 | D30: =IF(설정!$D$23="","",설정!$D$23) -> 25일
B31: =IF(설정!$B$24="","",설정!$B$24) -> 대출 이자 | C31: =IF(설정!$C$24="","",설정!$C$24) -> 180000 | D31: =IF(설정!$D$24="","",설정!$D$24) -> 25일
B32: =IF(설정!$B$25="","",설정!$B$25) -> 공과금 (전기·가스·수도) | C32: =IF(설정!$C$25="","",설정!$C$25) -> 140000 | D32: =IF(설정!$D$25="","",설정!$D$25) -> 말일
B33: =IF(설정!$B$26="","",설정!$B$26) | C33: =IF(설정!$C$26="","",설정!$C$26) | D33: =IF(설정!$D$26="","",설정!$D$26)
B34: =IF(설정!$B$27="","",설정!$B$27) | C34: =IF(설정!$C$27="","",설정!$C$27) | D34: =IF(설정!$D$27="","",설정!$D$27)
B35: 합계 | C35: =SUM(C23:C34) -> 1769000 | E35: =SUM(E23:E34) -> 0
B37: 저축·투자
B38: 항목 | C38: 목표 | D38: 실제 | E38: 차이
B39: =IF(설정!$B$49="","",설정!$B$49) -> 비상금 | C39: =IF(설정!$C$49="","",설정!$C$49) -> 150000 | E39: =IF(D39="","",D39-C39)
B40: =IF(설정!$B$50="","",설정!$B$50) -> 청약 / 내집마련 | C40: =IF(설정!$C$50="","",설정!$C$50) -> 100000 | E40: =IF(D40="","",D40-C40)
B41: =IF(설정!$B$51="","",설정!$B$51) -> 투자 (ETF·주식) | C41: =IF(설정!$C$51="","",설정!$C$51) -> 400000 | E41: =IF(D41="","",D41-C41)
...

Sheet 3월
B1: 3월 가계부 | L1: 제이슨의 머니쇼 · 2026 | V1: 월 지출(전체) 차트 데이터
V2: =IF(L5="","",L5) -> 식비 (장보기) | W2: =N5 -> 0
B3: 이번 달 한눈에 | G3: 변동지출 기록 | L3: 카테고리별 예산 vs 사용 | R3: 차트 데이터 | V3: =IF(L6="","",L6) -> 외식 / 카페 | W3: =N6 -> 0
B4: 총수입 | D4: =D19 -> 0 | G4: 날짜 | H4: 분류 | I4: 내용 | J4: 금액 | L4: 분류 | M4: 예산 | N4: 사용 | O4: 달성 | P4: 진행 | R4: 구분 | S4: 예산 | T4: 실제 | V4: =IF(L7="","",L7) -> 생활용품 | W4: =N7 -> 0
B5: 총지출 | D5: =E35+J55 -> 0 | L5: =IF(설정!$B$31="","",설정!$B$31) -> 식비 (장보기) | M5: =IF(설정!$C$31="","",설정!$C$31) -> 350000 | N5: =SUMIF($H$5:$H$54,L5,$J$5:$J$54) -> 0 | O5: =IFERROR(N5/M5,0) -> 0 | P5: =IF(M5="","",REPT("■",MIN(10,ROUND(O5*10,0)))&REPT("□",10-MIN(10,ROUND(O5*10,0)))) -> □□□□□□□□□□ | R5: 수입 | S5: =C19 -> 3950000 | T5: =D19 -> 0 | V5: =IF(L8="","",L8) -> 교통 / 차량 | W5: =N8 -> 0
B6: 저축·투자 | D6: =D45 -> 0 | L6: =IF(설정!$B$32="","",설정!$B$32) -> 외식 / 카페 | M6: =IF(설정!$C$32="","",설정!$C$32) -> 200000 | N6: =SUMIF($H$5:$H$54,L6,$J$5:$J$54) -> 0 | O6: =IFERROR(N6/M6,0) -> 0 | P6: =IF(M6="","",REPT("■",MIN(10,ROUND(O6*10,0)))&REPT("□",10-MIN(10,ROUND(O6*10,0)))) -> □□□□□□□□□□ | R6: 지출 | S6: =C35+M20 -> 3179000 | T6: =E35+J55 -> 0 | V6: =IF(L9="","",L9) -> 의료 / 건강 | W6: =N9 -> 0
B7: 남은 돈 | D7: =D4-D5-D6 -> 0 | L7: =IF(설정!$B$33="","",설정!$B$33) -> 생활용품 | M7: =IF(설정!$C$33="","",설정!$C$33) -> 80000 | N7: =SUMIF($H$5:$H$54,L7,$J$5:$J$54) -> 0 | O7: =IFERROR(N7/M7,0) -> 0 | P7: =IF(M7="","",REPT("■",MIN(10,ROUND(O7*10,0)))&REPT("□",10-MIN(10,ROUND(O7*10,0)))) -> □□□□□□□□□□ | R7: 저축 | S7: =C45 -> 1100000 | T7: =D45 -> 0 | V7: =IF(L10="","",L10) -> 의류 / 미용 | W7: =N10 -> 0
B8: 저축률 | D8: =IFERROR((D4-D5)/D4,0) -> 0 | L8: =IF(설정!$B$34="","",설정!$B$34) -> 교통 / 차량 | M8: =IF(설정!$C$34="","",설정!$C$34) -> 120000 | N8: =SUMIF($H$5:$H$54,L8,$J$5:$J$54) -> 0 | O8: =IFERROR(N8/M8,0) -> 0 | P8: =IF(M8="","",REPT("■",MIN(10,ROUND(O8*10,0)))&REPT("□",10-MIN(10,ROUND(O8*10,0)))) -> □□□□□□□□□□ | V8: =IF(L11="","",L11) -> 교육 / 자기계발 | W8: =N11 -> 0
L9: =IF(설정!$B$35="","",설정!$B$35) -> 의료 / 건강 | M9: =IF(설정!$C$35="","",설정!$C$35) -> 60000 | N9: =SUMIF($H$5:$H$54,L9,$J$5:$J$54) -> 0 | O9: =IFERROR(N9/M9,0) -> 0 | P9: =IF(M9="","",REPT("■",MIN(10,ROUND(O9*10,0)))&REPT("□",10-MIN(10,ROUND(O9*10,0)))) -> □□□□□□□□□□ | R9: 고정지출 | S9: =E35 -> 0 | V9: =IF(L12="","",L12) -> 문화 / 여가 | W9: =N12 -> 0
B10: 수입 | L10: =IF(설정!$B$36="","",설정!$B$36) -> 의류 / 미용 | M10: =IF(설정!$C$36="","",설정!$C$36) -> 100000 | N10: =SUMIF($H$5:$H$54,L10,$J$5:$J$54) -> 0 | O10: =IFERROR(N10/M10,0) -> 0 | P10: =IF(M10="","",REPT("■",MIN(10,ROUND(O10*10,0)))&REPT("□",10-MIN(10,ROUND(O10*10,0)))) -> □□□□□□□□□□ | R10: 변동지출 | S10: =J55 -> 0 | V10: =IF(L13="","",L13) -> 경조사 / 선물 | W10: =N13 -> 0
B11: 항목 | C11: 예상 | D11: 실제 | E11: 차이 | L11: =IF(설정!$B$37="","",설정!$B$37) -> 교육 / 자기계발 | M11: =IF(설정!$C$37="","",설정!$C$37) -> 80000 | N11: =SUMIF($H$5:$H$54,L11,$J$5:$J$54) -> 0 | O11: =IFERROR(N11/M11,0) -> 0 | P11: =IF(M11="","",REPT("■",MIN(10,ROUND(O11*10,0)))&REPT("□",10-MIN(10,ROUND(O11*10,0)))) -> □□□□□□□□□□ | V11: =IF(L14="","",L14) -> 자녀 / 육아 | W11: =N14 -> 0
B12: =IF(설정!$B$6="","",설정!$B$6) -> 월급 (본업) | C12: =IF(설정!$C$6="","",설정!$C$6) -> 3500000 | E12: =IF(D12="","",D12-C12) | L12: =IF(설정!$B$38="","",설정!$B$38) -> 문화 / 여가 | M12: =IF(설정!$C$38="","",설정!$C$38) -> 80000 | N12: =SUMIF($H$5:$H$54,L12,$J$5:$J$54) -> 0 | O12: =IFERROR(N12/M12,0) -> 0 | P12: =IF(M12="","",REPT("■",MIN(10,ROUND(O12*10,0)))&REPT("□",10-MIN(10,ROUND(O12*10,0)))) -> □□□□□□□□□□ | V12: =IF(L15="","",L15) -> 반려동물 | W12: =N15 -> 0
B13: =IF(설정!$B$7="","",설정!$B$7) -> 부수입 / 사이드잡 | C13: =IF(설정!$C$7="","",설정!$C$7) -> 400000 | E13: =IF(D13="","",D13-C13) | L13: =IF(설정!$B$39="","",설정!$B$39) -> 경조사 / 선물 | M13: =IF(설정!$C$39="","",설정!$C$39) -> 100000 | N13: =SUMIF($H$5:$H$54,L13,$J$5:$J$54) -> 0 | O13: =IFERROR(N13/M13,0) -> 0 | P13: =IF(M13="","",REPT("■",MIN(10,ROUND(O13*10,0)))&REPT("□",10-MIN(10,ROUND(O13*10,0)))) -> □□□□□□□□□□ | V13: =IF(L16="","",L16) -> 여행 | W13: =N16 -> 0
B14: =IF(설정!$B$8="","",설정!$B$8) -> 상여 / 보너스 | C14: =IF(설정!$C$8="","",설정!$C$8) -> 0 | E14: =IF(D14="","",D14-C14) | L14: =IF(설정!$B$40="","",설정!$B$40) -> 자녀 / 육아 | M14: =IF(설정!$C$40="","",설정!$C$40) -> 0 | N14: =SUMIF($H$5:$H$54,L14,$J$5:$J$54) -> 0 | O14: =IFERROR(N14/M14,0) -> 0 | P14: =IF(M14="","",REPT("■",MIN(10,ROUND(O14*10,0)))&REPT("□",10-MIN(10,ROUND(O14*10,0)))) -> □□□□□□□□□□ | V14: =IF(L17="","",L17) -> 통신 / 디지털 | W14: =N17 -> 0
B15: =IF(설정!$B$9="","",설정!$B$9) -> 이자 / 배당 | C15: =IF(설정!$C$9="","",설정!$C$9) -> 50000 | E15: =IF(D15="","",D15-C15) | L15: =IF(설정!$B$41="","",설정!$B$41) -> 반려동물 | M15: =IF(설정!$C$41="","",설정!$C$41) -> 0 | N15: =SUMIF($H$5:$H$54,L15,$J$5:$J$54) -> 0 | O15: =IFERROR(N15/M15,0) -> 0 | P15: =IF(M15="","",REPT("■",MIN(10,ROUND(O15*10,0)))&REPT("□",10-MIN(10,ROUND(O15*10,0)))) -> □□□□□□□□□□ | V15: =IF(L18="","",L18) -> 기부 / 후원 | W15: =N18 -> 0
B16: =IF(설정!$B$10="","",설정!$B$10) -> 용돈 / 기타 | C16: =IF(설정!$C$10="","",설정!$C$10) -> 0 | E16: =IF(D16="","",D16-C16) | L16: =IF(설정!$B$42="","",설정!$B$42) -> 여행 | M16: =IF(설정!$C$42="","",설정!$C$42) -> 100000 | N16: =SUMIF($H$5:$H$54,L16,$J$5:$J$54) -> 0 | O16: =IFERROR(N16/M16,0) -> 0 | P16: =IF(M16="","",REPT("■",MIN(10,ROUND(O16*10,0)))&REPT("□",10-MIN(10,ROUND(O16*10,0)))) -> □□□□□□□□□□ | V16: =IF(L19="","",L19) -> 기타 | W16: =N19 -> 0
B17: =IF(설정!$B$11="","",설정!$B$11) | C17: =IF(설정!$C$11="","",설정!$C$11) | E17: =IF(D17="","",D17-C17) | L17: =IF(설정!$B$43="","",설정!$B$43) -> 통신 / 디지털 | M17: =IF(설정!$C$43="","",설정!$C$43) -> 30000 | N17: =SUMIF($H$5:$H$54,L17,$J$5:$J$54) -> 0 | O17: =IFERROR(N17/M17,0) -> 0 | P17: =IF(M17="","",REPT("■",MIN(10,ROUND(O17*10,0)))&REPT("□",10-MIN(10,ROUND(O17*10,0)))) -> □□□□□□□□□□ | V17: =IF(B23="","",B23) -> 월세 / 주택대출 상환 | W17: =E23 -> 0
B18: =IF(설정!$B$12="","",설정!$B$12) | C18: =IF(설정!$C$12="","",설정!$C$12) | E18: =IF(D18="","",D18-C18) | L18: =IF(설정!$B$44="","",설정!$B$44) -> 기부 / 후원 | M18: =IF(설정!$C$44="","",설정!$C$44) -> 30000 | N18: =SUMIF($H$5:$H$54,L18,$J$5:$J$54) -> 0 | O18: =IFERROR(N18/M18,0) -> 0 | P18: =IF(M18="","",REPT("■",MIN(10,ROUND(O18*10,0)))&REPT("□",10-MIN(10,ROUND(O18*10,0)))) -> □□□□□□□□□□ | V18: =IF(B24="","",B24) -> 관리비 | W18: =E24 -> 0
B19: 합계 | C19: =SUM(C12:C18) -> 3950000 | D19: =SUM(D12:D18) -> 0 | E19: =D19-C19 -> -3950000 | L19: =IF(설정!$B$45="","",설정!$B$45) -> 기타 | M19: =IF(설정!$C$45="","",설정!$C$45) -> 80000 | N19: =SUMIF($H$5:$H$54,L19,$J$5:$J$54) -> 0 | O19: =IFERROR(N19/M19,0) -> 0 | P19: =IF(M19="","",REPT("■",MIN(10,ROUND(O19*10,0)))&REPT("□",10-MIN(10,ROUND(O19*10,0)))) -> □□□□□□□□□□ | V19: =IF(B25="","",B25) -> 통신비 (휴대폰·인터넷) | W19: =E25 -> 0
L20: 합계 | M20: =SUM(M5:M19) -> 1410000 | N20: =SUM(N5:N19) -> 0 | V20: =IF(B26="","",B26) -> 보험료 | W20: =E26 -> 0
B21: 고정지출 | V21: =IF(B27="","",B27) -> 구독 서비스 | W21: =E27 -> 0
B22: 항목 | C22: 예산 | D22: 결제일 | E22: 실제 | V22: =IF(B28="","",B28) -> 교통 정기권 | W22: =E28 -> 0
B23: =IF(설정!$B$16="","",설정!$B$16) -> 월세 / 주택대출 상환 | C23: =IF(설정!$C$16="","",설정!$C$16) -> 600000 | D23: =IF(설정!$D$16="","",설정!$D$16) -> 25일 | V23: =IF(B29="","",B29) -> 적금 | W23: =E29 -> 0
B24: =IF(설정!$B$17="","",설정!$B$17) -> 관리비 | C24: =IF(설정!$C$17="","",설정!$C$17) -> 150000 | D24: =IF(설정!$D$17="","",설정!$D$17) -> 30일 | V24: =IF(B30="","",B30) -> 청약저축 | W24: =E30 -> 0
B25: =IF(설정!$B$18="","",설정!$B$18) -> 통신비 (휴대폰·인터넷) | C25: =IF(설정!$C$18="","",설정!$C$18) -> 88000 | D25: =IF(설정!$D$18="","",설정!$D$18) -> 15일 | V25: =IF(B31="","",B31) -> 대출 이자 | W25: =E31 -> 0
B26: =IF(설정!$B$19="","",설정!$B$19) -> 보험료 | C26: =IF(설정!$C$19="","",설정!$C$19) -> 120000 | D26: =IF(설정!$D$19="","",설정!$D$19) -> 5일 | V26: =IF(B32="","",B32) -> 공과금 (전기·가스·수도) | W26: =E32 -> 0
B27: =IF(설정!$B$20="","",설정!$B$20) -> 구독 서비스 | C27: =IF(설정!$C$20="","",설정!$C$20) -> 29000 | D27: =IF(설정!$D$20="","",설정!$D$20) -> 10일 | V27: =IF(B33="","",B33) | W27: =E33 -> 0
B28: =IF(설정!$B$21="","",설정!$B$21) -> 교통 정기권 | C28: =IF(설정!$C$21="","",설정!$C$21) -> 62000 | D28: =IF(설정!$D$21="","",설정!$D$21) -> 1일 | V28: =IF(B34="","",B34) | W28: =E34 -> 0
B29: =IF(설정!$B$22="","",설정!$B$22) -> 적금 | C29: =IF(설정!$C$22="","",설정!$C$22) -> 300000 | D29: =IF(설정!$D$22="","",설정!$D$22) -> 25일
B30: =IF(설정!$B$23="","",설정!$B$23) -> 청약저축 | C30: =IF(설정!$C$23="","",설정!$C$23) -> 100000 | D30: =IF(설정!$D$23="","",설정!$D$23) -> 25일
B31: =IF(설정!$B$24="","",설정!$B$24) -> 대출 이자 | C31: =IF(설정!$C$24="","",설정!$C$24) -> 180000 | D31: =IF(설정!$D$24="","",설정!$D$24) -> 25일
B32: =IF(설정!$B$25="","",설정!$B$25) -> 공과금 (전기·가스·수도) | C32: =IF(설정!$C$25="","",설정!$C$25) -> 140000 | D32: =IF(설정!$D$25="","",설정!$D$25) -> 말일
B33: =IF(설정!$B$26="","",설정!$B$26) | C33: =IF(설정!$C$26="","",설정!$C$26) | D33: =IF(설정!$D$26="","",설정!$D$26)
B34: =IF(설정!$B$27="","",설정!$B$27) | C34: =IF(설정!$C$27="","",설정!$C$27) | D34: =IF(설정!$D$27="","",설정!$D$27)
B35: 합계 | C35: =SUM(C23:C34) -> 1769000 | E35: =SUM(E23:E34) -> 0
B37: 저축·투자
B38: 항목 | C38: 목표 | D38: 실제 | E38: 차이
B39: =IF(설정!$B$49="","",설정!$B$49) -> 비상금 | C39: =IF(설정!$C$49="","",설정!$C$49) -> 150000 | E39: =IF(D39="","",D39-C39)
B40: =IF(설정!$B$50="","",설정!$B$50) -> 청약 / 내집마련 | C40: =IF(설정!$C$50="","",설정!$C$50) -> 100000 | E40: =IF(D40="","",D40-C40)
B41: =IF(설정!$B$51="","",설정!$B$51) -> 투자 (ETF·주식) | C41: =IF(설정!$C$51="","",설정!$C$51) -> 400000 | E41: =IF(D41="","",D41-C41)
...

Sheet 4월
B1: 4월 가계부 | L1: 제이슨의 머니쇼 · 2026 | V1: 월 지출(전체) 차트 데이터
V2: =IF(L5="","",L5) -> 식비 (장보기) | W2: =N5 -> 0
B3: 이번 달 한눈에 | G3: 변동지출 기록 | L3: 카테고리별 예산 vs 사용 | R3: 차트 데이터 | V3: =IF(L6="","",L6) -> 외식 / 카페 | W3: =N6 -> 0
B4: 총수입 | D4: =D19 -> 0 | G4: 날짜 | H4: 분류 | I4: 내용 | J4: 금액 | L4: 분류 | M4: 예산 | N4: 사용 | O4: 달성 | P4: 진행 | R4: 구분 | S4: 예산 | T4: 실제 | V4: =IF(L7="","",L7) -> 생활용품 | W4: =N7 -> 0
B5: 총지출 | D5: =E35+J55 -> 0 | L5: =IF(설정!$B$31="","",설정!$B$31) -> 식비 (장보기) | M5: =IF(설정!$C$31="","",설정!$C$31) -> 350000 | N5: =SUMIF($H$5:$H$54,L5,$J$5:$J$54) -> 0 | O5: =IFERROR(N5/M5,0) -> 0 | P5: =IF(M5="","",REPT("■",MIN(10,ROUND(O5*10,0)))&REPT("□",10-MIN(10,ROUND(O5*10,0)))) -> □□□□□□□□□□ | R5: 수입 | S5: =C19 -> 3950000 | T5: =D19 -> 0 | V5: =IF(L8="","",L8) -> 교통 / 차량 | W5: =N8 -> 0
B6: 저축·투자 | D6: =D45 -> 0 | L6: =IF(설정!$B$32="","",설정!$B$32) -> 외식 / 카페 | M6: =IF(설정!$C$32="","",설정!$C$32) -> 200000 | N6: =SUMIF($H$5:$H$54,L6,$J$5:$J$54) -> 0 | O6: =IFERROR(N6/M6,0) -> 0 | P6: =IF(M6="","",REPT("■",MIN(10,ROUND(O6*10,0)))&REPT("□",10-MIN(10,ROUND(O6*10,0)))) -> □□□□□□□□□□ | R6: 지출 | S6: =C35+M20 -> 3179000 | T6: =E35+J55 -> 0 | V6: =IF(L9="","",L9) -> 의료 / 건강 | W6: =N9 -> 0
B7: 남은 돈 | D7: =D4-D5-D6 -> 0 | L7: =IF(설정!$B$33="","",설정!$B$33) -> 생활용품 | M7: =IF(설정!$C$33="","",설정!$C$33) -> 80000 | N7: =SUMIF($H$5:$H$54,L7,$J$5:$J$54) -> 0 | O7: =IFERROR(N7/M7,0) -> 0 | P7: =IF(M7="","",REPT("■",MIN(10,ROUND(O7*10,0)))&REPT("□",10-MIN(10,ROUND(O7*10,0)))) -> □□□□□□□□□□ | R7: 저축 | S7: =C45 -> 1100000 | T7: =D45 -> 0 | V7: =IF(L10="","",L10) -> 의류 / 미용 | W7: =N10 -> 0
B8: 저축률 | D8: =IFERROR((D4-D5)/D4,0) -> 0 | L8: =IF(설정!$B$34="","",설정!$B$34) -> 교통 / 차량 | M8: =IF(설정!$C$34="","",설정!$C$34) -> 120000 | N8: =SUMIF($H$5:$H$54,L8,$J$5:$J$54) -> 0 | O8: =IFERROR(N8/M8,0) -> 0 | P8: =IF(M8="","",REPT("■",MIN(10,ROUND(O8*10,0)))&REPT("□",10-MIN(10,ROUND(O8*10,0)))) -> □□□□□□□□□□ | V8: =IF(L11="","",L11) -> 교육 / 자기계발 | W8: =N11 -> 0
L9: =IF(설정!$B$35="","",설정!$B$35) -> 의료 / 건강 | M9: =IF(설정!$C$35="","",설정!$C$35) -> 60000 | N9: =SUMIF($H$5:$H$54,L9,$J$5:$J$54) -> 0 | O9: =IFERROR(N9/M9,0) -> 0 | P9: =IF(M9="","",REPT("■",MIN(10,ROUND(O9*10,0)))&REPT("□",10-MIN(10,ROUND(O9*10,0)))) -> □□□□□□□□□□ | R9: 고정지출 | S9: =E35 -> 0 | V9: =IF(L12="","",L12) -> 문화 / 여가 | W9: =N12 -> 0
B10: 수입 | L10: =IF(설정!$B$36="","",설정!$B$36) -> 의류 / 미용 | M10: =IF(설정!$C$36="","",설정!$C$36) -> 100000 | N10: =SUMIF($H$5:$H$54,L10,$J$5:$J$54) -> 0 | O10: =IFERROR(N10/M10,0) -> 0 | P10: =IF(M10="","",REPT("■",MIN(10,ROUND(O10*10,0)))&REPT("□",10-MIN(10,ROUND(O10*10,0)))) -> □□□□□□□□□□ | R10: 변동지출 | S10: =J55 -> 0 | V10: =IF(L13="","",L13) -> 경조사 / 선물 | W10: =N13 -> 0
B11: 항목 | C11: 예상 | D11: 실제 | E11: 차이 | L11: =IF(설정!$B$37="","",설정!$B$37) -> 교육 / 자기계발 | M11: =IF(설정!$C$37="","",설정!$C$37) -> 80000 | N11: =SUMIF($H$5:$H$54,L11,$J$5:$J$54) -> 0 | O11: =IFERROR(N11/M11,0) -> 0 | P11: =IF(M11="","",REPT("■",MIN(10,ROUND(O11*10,0)))&REPT("□",10-MIN(10,ROUND(O11*10,0)))) -> □□□□□□□□□□ | V11: =IF(L14="","",L14) -> 자녀 / 육아 | W11: =N14 -> 0
B12: =IF(설정!$B$6="","",설정!$B$6) -> 월급 (본업) | C12: =IF(설정!$C$6="","",설정!$C$6) -> 3500000 | E12: =IF(D12="","",D12-C12) | L12: =IF(설정!$B$38="","",설정!$B$38) -> 문화 / 여가 | M12: =IF(설정!$C$38="","",설정!$C$38) -> 80000 | N12: =SUMIF($H$5:$H$54,L12,$J$5:$J$54) -> 0 | O12: =IFERROR(N12/M12,0) -> 0 | P12: =IF(M12="","",REPT("■",MIN(10,ROUND(O12*10,0)))&REPT("□",10-MIN(10,ROUND(O12*10,0)))) -> □□□□□□□□□□ | V12: =IF(L15="","",L15) -> 반려동물 | W12: =N15 -> 0
B13: =IF(설정!$B$7="","",설정!$B$7) -> 부수입 / 사이드잡 | C13: =IF(설정!$C$7="","",설정!$C$7) -> 400000 | E13: =IF(D13="","",D13-C13) | L13: =IF(설정!$B$39="","",설정!$B$39) -> 경조사 / 선물 | M13: =IF(설정!$C$39="","",설정!$C$39) -> 100000 | N13: =SUMIF($H$5:$H$54,L13,$J$5:$J$54) -> 0 | O13: =IFERROR(N13/M13,0) -> 0 | P13: =IF(M13="","",REPT("■",MIN(10,ROUND(O13*10,0)))&REPT("□",10-MIN(10,ROUND(O13*10,0)))) -> □□□□□□□□□□ | V13: =IF(L16="","",L16) -> 여행 | W13: =N16 -> 0
B14: =IF(설정!$B$8="","",설정!$B$8) -> 상여 / 보너스 | C14: =IF(설정!$C$8="","",설정!$C$8) -> 0 | E14: =IF(D14="","",D14-C14) | L14: =IF(설정!$B$40="","",설정!$B$40) -> 자녀 / 육아 | M14: =IF(설정!$C$40="","",설정!$C$40) -> 0 | N14: =SUMIF($H$5:$H$54,L14,$J$5:$J$54) -> 0 | O14: =IFERROR(N14/M14,0) -> 0 | P14: =IF(M14="","",REPT("■",MIN(10,ROUND(O14*10,0)))&REPT("□",10-MIN(10,ROUND(O14*10,0)))) -> □□□□□□□□□□ | V14: =IF(L17="","",L17) -> 통신 / 디지털 | W14: =N17 -> 0
B15: =IF(설정!$B$9="","",설정!$B$9) -> 이자 / 배당 | C15: =IF(설정!$C$9="","",설정!$C$9) -> 50000 | E15: =IF(D15="","",D15-C15) | L15: =IF(설정!$B$41="","",설정!$B$41) -> 반려동물 | M15: =IF(설정!$C$41="","",설정!$C$41) -> 0 | N15: =SUMIF($H$5:$H$54,L15,$J$5:$J$54) -> 0 | O15: =IFERROR(N15/M15,0) -> 0 | P15: =IF(M15="","",REPT("■",MIN(10,ROUND(O15*10,0)))&REPT("□",10-MIN(10,ROUND(O15*10,0)))) -> □□□□□□□□□□ | V15: =IF(L18="","",L18) -> 기부 / 후원 | W15: =N18 -> 0
B16: =IF(설정!$B$10="","",설정!$B$10) -> 용돈 / 기타 | C16: =IF(설정!$C$10="","",설정!$C$10) -> 0 | E16: =IF(D16="","",D16-C16) | L16: =IF(설정!$B$42="","",설정!$B$42) -> 여행 | M16: =IF(설정!$C$42="","",설정!$C$42) -> 100000 | N16: =SUMIF($H$5:$H$54,L16,$J$5:$J$54) -> 0 | O16: =IFERROR(N16/M16,0) -> 0 | P16: =IF(M16="","",REPT("■",MIN(10,ROUND(O16*10,0)))&REPT("□",10-MIN(10,ROUND(O16*10,0)))) -> □□□□□□□□□□ | V16: =IF(L19="","",L19) -> 기타 | W16: =N19 -> 0
B17: =IF(설정!$B$11="","",설정!$B$11) | C17: =IF(설정!$C$11="","",설정!$C$11) | E17: =IF(D17="","",D17-C17) | L17: =IF(설정!$B$43="","",설정!$B$43) -> 통신 / 디지털 | M17: =IF(설정!$C$43="","",설정!$C$43) -> 30000 | N17: =SUMIF($H$5:$H$54,L17,$J$5:$J$54) -> 0 | O17: =IFERROR(N17/M17,0) -> 0 | P17: =IF(M17="","",REPT("■",MIN(10,ROUND(O17*10,0)))&REPT("□",10-MIN(10,ROUND(O17*10,0)))) -> □□□□□□□□□□ | V17: =IF(B23="","",B23) -> 월세 / 주택대출 상환 | W17: =E23 -> 0
B18: =IF(설정!$B$12="","",설정!$B$12) | C18: =IF(설정!$C$12="","",설정!$C$12) | E18: =IF(D18="","",D18-C18) | L18: =IF(설정!$B$44="","",설정!$B$44) -> 기부 / 후원 | M18: =IF(설정!$C$44="","",설정!$C$44) -> 30000 | N18: =SUMIF($H$5:$H$54,L18,$J$5:$J$54) -> 0 | O18: =IFERROR(N18/M18,0) -> 0 | P18: =IF(M18="","",REPT("■",MIN(10,ROUND(O18*10,0)))&REPT("□",10-MIN(10,ROUND(O18*10,0)))) -> □□□□□□□□□□ | V18: =IF(B24="","",B24) -> 관리비 | W18: =E24 -> 0
B19: 합계 | C19: =SUM(C12:C18) -> 3950000 | D19: =SUM(D12:D18) -> 0 | E19: =D19-C19 -> -3950000 | L19: =IF(설정!$B$45="","",설정!$B$45) -> 기타 | M19: =IF(설정!$C$45="","",설정!$C$45) -> 80000 | N19: =SUMIF($H$5:$H$54,L19,$J$5:$J$54) -> 0 | O19: =IFERROR(N19/M19,0) -> 0 | P19: =IF(M19="","",REPT("■",MIN(10,ROUND(O19*10,0)))&REPT("□",10-MIN(10,ROUND(O19*10,0)))) -> □□□□□□□□□□ | V19: =IF(B25="","",B25) -> 통신비 (휴대폰·인터넷) | W19: =E25 -> 0
L20: 합계 | M20: =SUM(M5:M19) -> 1410000 | N20: =SUM(N5:N19) -> 0 | V20: =IF(B26="","",B26) -> 보험료 | W20: =E26 -> 0
B21: 고정지출 | V21: =IF(B27="","",B27) -> 구독 서비스 | W21: =E27 -> 0
B22: 항목 | C22: 예산 | D22: 결제일 | E22: 실제 | V22: =IF(B28="","",B28) -> 교통 정기권 | W22: =E28 -> 0
B23: =IF(설정!$B$16="","",설정!$B$16) -> 월세 / 주택대출 상환 | C23: =IF(설정!$C$16="","",설정!$C$16) -> 600000 | D23: =IF(설정!$D$16="","",설정!$D$16) -> 25일 | V23: =IF(B29="","",B29) -> 적금 | W23: =E29 -> 0
B24: =IF(설정!$B$17="","",설정!$B$17) -> 관리비 | C24: =IF(설정!$C$17="","",설정!$C$17) -> 150000 | D24: =IF(설정!$D$17="","",설정!$D$17) -> 30일 | V24: =IF(B30="","",B30) -> 청약저축 | W24: =E30 -> 0
B25: =IF(설정!$B$18="","",설정!$B$18) -> 통신비 (휴대폰·인터넷) | C25: =IF(설정!$C$18="","",설정!$C$18) -> 88000 | D25: =IF(설정!$D$18="","",설정!$D$18) -> 15일 | V25: =IF(B31="","",B31) -> 대출 이자 | W25: =E31 -> 0
B26: =IF(설정!$B$19="","",설정!$B$19) -> 보험료 | C26: =IF(설정!$C$19="","",설정!$C$19) -> 120000 | D26: =IF(설정!$D$19="","",설정!$D$19) -> 5일 | V26: =IF(B32="","",B32) -> 공과금 (전기·가스·수도) | W26: =E32 -> 0
B27: =IF(설정!$B$20="","",설정!$B$20) -> 구독 서비스 | C27: =IF(설정!$C$20="","",설정!$C$20) -> 29000 | D27: =IF(설정!$D$20="","",설정!$D$20) -> 10일 | V27: =IF(B33="","",B33) | W27: =E33 -> 0
B28: =IF(설정!$B$21="","",설정!$B$21) -> 교통 정기권 | C28: =IF(설정!$C$21="","",설정!$C$21) -> 62000 | D28: =IF(설정!$D$21="","",설정!$D$21) -> 1일 | V28: =IF(B34="","",B34) | W28: =E34 -> 0
B29: =IF(설정!$B$22="","",설정!$B$22) -> 적금 | C29: =IF(설정!$C$22="","",설정!$C$22) -> 300000 | D29: =IF(설정!$D$22="","",설정!$D$22) -> 25일
B30: =IF(설정!$B$23="","",설정!$B$23) -> 청약저축 | C30: =IF(설정!$C$23="","",설정!$C$23) -> 100000 | D30: =IF(설정!$D$23="","",설정!$D$23) -> 25일
B31: =IF(설정!$B$24="","",설정!$B$24) -> 대출 이자 | C31: =IF(설정!$C$24="","",설정!$C$24) -> 180000 | D31: =IF(설정!$D$24="","",설정!$D$24) -> 25일
B32: =IF(설정!$B$25="","",설정!$B$25) -> 공과금 (전기·가스·수도) | C32: =IF(설정!$C$25="","",설정!$C$25) -> 140000 | D32: =IF(설정!$D$25="","",설정!$D$25) -> 말일
B33: =IF(설정!$B$26="","",설정!$B$26) | C33: =IF(설정!$C$26="","",설정!$C$26) | D33: =IF(설정!$D$26="","",설정!$D$26)
B34: =IF(설정!$B$27="","",설정!$B$27) | C34: =IF(설정!$C$27="","",설정!$C$27) | D34: =IF(설정!$D$27="","",설정!$D$27)
B35: 합계 | C35: =SUM(C23:C34) -> 1769000 | E35: =SUM(E23:E34) -> 0
B37: 저축·투자
B38: 항목 | C38: 목표 | D38: 실제 | E38: 차이
B39: =IF(설정!$B$49="","",설정!$B$49) -> 비상금 | C39: =IF(설정!$C$49="","",설정!$C$49) -> 150000 | E39: =IF(D39="","",D39-C39)
B40: =IF(설정!$B$50="","",설정!$B$50) -> 청약 / 내집마련 | C40: =IF(설정!$C$50="","",설정!$C$50) -> 100000 | E40: =IF(D40="","",D40-C40)
B41: =IF(설정!$B$51="","",설정!$B$51) -> 투자 (ETF·주식) | C41: =IF(설정!$C$51="","",설정!$C$51) -> 400000 | E41: =IF(D41="","",D41-C41)
...

Sheet 5월
B1: 5월 가계부 | L1: 제이슨의 머니쇼 · 2026 | V1: 월 지출(전체) 차트 데이터
V2: =IF(L5="","",L5) -> 식비 (장보기) | W2: =N5 -> 0
B3: 이번 달 한눈에 | G3: 변동지출 기록 | L3: 카테고리별 예산 vs 사용 | R3: 차트 데이터 | V3: =IF(L6="","",L6) -> 외식 / 카페 | W3: =N6 -> 0
B4: 총수입 | D4: =D19 -> 0 | G4: 날짜 | H4: 분류 | I4: 내용 | J4: 금액 | L4: 분류 | M4: 예산 | N4: 사용 | O4: 달성 | P4: 진행 | R4: 구분 | S4: 예산 | T4: 실제 | V4: =IF(L7="","",L7) -> 생활용품 | W4: =N7 -> 0
B5: 총지출 | D5: =E35+J55 -> 0 | L5: =IF(설정!$B$31="","",설정!$B$31) -> 식비 (장보기) | M5: =IF(설정!$C$31="","",설정!$C$31) -> 350000 | N5: =SUMIF($H$5:$H$54,L5,$J$5:$J$54) -> 0 | O5: =IFERROR(N5/M5,0) -> 0 | P5: =IF(M5="","",REPT("■",MIN(10,ROUND(O5*10,0)))&REPT("□",10-MIN(10,ROUND(O5*10,0)))) -> □□□□□□□□□□ | R5: 수입 | S5: =C19 -> 3950000 | T5: =D19 -> 0 | V5: =IF(L8="","",L8) -> 교통 / 차량 | W5: =N8 -> 0
B6: 저축·투자 | D6: =D45 -> 0 | L6: =IF(설정!$B$32="","",설정!$B$32) -> 외식 / 카페 | M6: =IF(설정!$C$32="","",설정!$C$32) -> 200000 | N6: =SUMIF($H$5:$H$54,L6,$J$5:$J$54) -> 0 | O6: =IFERROR(N6/M6,0) -> 0 | P6: =IF(M6="","",REPT("■",MIN(10,ROUND(O6*10,0)))&REPT("□",10-MIN(10,ROUND(O6*10,0)))) -> □□□□□□□□□□ | R6: 지출 | S6: =C35+M20 -> 3179000 | T6: =E35+J55 -> 0 | V6: =IF(L9="","",L9) -> 의료 / 건강 | W6: =N9 -> 0
B7: 남은 돈 | D7: =D4-D5-D6 -> 0 | L7: =IF(설정!$B$33="","",설정!$B$33) -> 생활용품 | M7: =IF(설정!$C$33="","",설정!$C$33) -> 80000 | N7: =SUMIF($H$5:$H$54,L7,$J$5:$J$54) -> 0 | O7: =IFERROR(N7/M7,0) -> 0 | P7: =IF(M7="","",REPT("■",MIN(10,ROUND(O7*10,0)))&REPT("□",10-MIN(10,ROUND(O7*10,0)))) -> □□□□□□□□□□ | R7: 저축 | S7: =C45 -> 1100000 | T7: =D45 -> 0 | V7: =IF(L10="","",L10) -> 의류 / 미용 | W7: =N10 -> 0
B8: 저축률 | D8: =IFERROR((D4-D5)/D4,0) -> 0 | L8: =IF(설정!$B$34="","",설정!$B$34) -> 교통 / 차량 | M8: =IF(설정!$C$34="","",설정!$C$34) -> 120000 | N8: =SUMIF($H$5:$H$54,L8,$J$5:$J$54) -> 0 | O8: =IFERROR(N8/M8,0) -> 0 | P8: =IF(M8="","",REPT("■",MIN(10,ROUND(O8*10,0)))&REPT("□",10-MIN(10,ROUND(O8*10,0)))) -> □□□□□□□□□□ | V8: =IF(L11="","",L11) -> 교육 / 자기계발 | W8: =N11 -> 0
L9: =IF(설정!$B$35="","",설정!$B$35) -> 의료 / 건강 | M9: =IF(설정!$C$35="","",설정!$C$35) -> 60000 | N9: =SUMIF($H$5:$H$54,L9,$J$5:$J$54) -> 0 | O9: =IFERROR(N9/M9,0) -> 0 | P9: =IF(M9="","",REPT("■",MIN(10,ROUND(O9*10,0)))&REPT("□",10-MIN(10,ROUND(O9*10,0)))) -> □□□□□□□□□□ | R9: 고정지출 | S9: =E35 -> 0 | V9: =IF(L12="","",L12) -> 문화 / 여가 | W9: =N12 -> 0
B10: 수입 | L10: =IF(설정!$B$36="","",설정!$B$36) -> 의류 / 미용 | M10: =IF(설정!$C$36="","",설정!$C$36) -> 100000 | N10: =SUMIF($H$5:$H$54,L10,$J$5:$J$54) -> 0 | O10: =IFERROR(N10/M10,0) -> 0 | P10: =IF(M10="","",REPT("■",MIN(10,ROUND(O10*10,0)))&REPT("□",10-MIN(10,ROUND(O10*10,0)))) -> □□□□□□□□□□ | R10: 변동지출 | S10: =J55 -> 0 | V10: =IF(L13="","",L13) -> 경조사 / 선물 | W10: =N13 -> 0
B11: 항목 | C11: 예상 | D11: 실제 | E11: 차이 | L11: =IF(설정!$B$37="","",설정!$B$37) -> 교육 / 자기계발 | M11: =IF(설정!$C$37="","",설정!$C$37) -> 80000 | N11: =SUMIF($H$5:$H$54,L11,$J$5:$J$54) -> 0 | O11: =IFERROR(N11/M11,0) -> 0 | P11: =IF(M11="","",REPT("■",MIN(10,ROUND(O11*10,0)))&REPT("□",10-MIN(10,ROUND(O11*10,0)))) -> □□□□□□□□□□ | V11: =IF(L14="","",L14) -> 자녀 / 육아 | W11: =N14 -> 0
B12: =IF(설정!$B$6="","",설정!$B$6) -> 월급 (본업) | C12: =IF(설정!$C$6="","",설정!$C$6) -> 3500000 | E12: =IF(D12="","",D12-C12) | L12: =IF(설정!$B$38="","",설정!$B$38) -> 문화 / 여가 | M12: =IF(설정!$C$38="","",설정!$C$38) -> 80000 | N12: =SUMIF($H$5:$H$54,L12,$J$5:$J$54) -> 0 | O12: =IFERROR(N12/M12,0) -> 0 | P12: =IF(M12="","",REPT("■",MIN(10,ROUND(O12*10,0)))&REPT("□",10-MIN(10,ROUND(O12*10,0)))) -> □□□□□□□□□□ | V12: =IF(L15="","",L15) -> 반려동물 | W12: =N15 -> 0
B13: =IF(설정!$B$7="","",설정!$B$7) -> 부수입 / 사이드잡 | C13: =IF(설정!$C$7="","",설정!$C$7) -> 400000 | E13: =IF(D13="","",D13-C13) | L13: =IF(설정!$B$39="","",설정!$B$39) -> 경조사 / 선물 | M13: =IF(설정!$C$39="","",설정!$C$39) -> 100000 | N13: =SUMIF($H$5:$H$54,L13,$J$5:$J$54) -> 0 | O13: =IFERROR(N13/M13,0) -> 0 | P13: =IF(M13="","",REPT("■",MIN(10,ROUND(O13*10,0)))&REPT("□",10-MIN(10,ROUND(O13*10,0)))) -> □□□□□□□□□□ | V13: =IF(L16="","",L16) -> 여행 | W13: =N16 -> 0
B14: =IF(설정!$B$8="","",설정!$B$8) -> 상여 / 보너스 | C14: =IF(설정!$C$8="","",설정!$C$8) -> 0 | E14: =IF(D14="","",D14-C14) | L14: =IF(설정!$B$40="","",설정!$B$40) -> 자녀 / 육아 | M14: =IF(설정!$C$40="","",설정!$C$40) -> 0 | N14: =SUMIF($H$5:$H$54,L14,$J$5:$J$54) -> 0 | O14: =IFERROR(N14/M14,0) -> 0 | P14: =IF(M14="","",REPT("■",MIN(10,ROUND(O14*10,0)))&REPT("□",10-MIN(10,ROUND(O14*10,0)))) -> □□□□□□□□□□ | V14: =IF(L17="","",L17) -> 통신 / 디지털 | W14: =N17 -> 0
B15: =IF(설정!$B$9="","",설정!$B$9) -> 이자 / 배당 | C15: =IF(설정!$C$9="","",설정!$C$9) -> 50000 | E15: =IF(D15="","",D15-C15) | L15: =IF(설정!$B$41="","",설정!$B$41) -> 반려동물 | M15: =IF(설정!$C$41="","",설정!$C$41) -> 0 | N15: =SUMIF($H$5:$H$54,L15,$J$5:$J$54) -> 0 | O15: =IFERROR(N15/M15,0) -> 0 | P15: =IF(M15="","",REPT("■",MIN(10,ROUND(O15*10,0)))&REPT("□",10-MIN(10,ROUND(O15*10,0)))) -> □□□□□□□□□□ | V15: =IF(L18="","",L18) -> 기부 / 후원 | W15: =N18 -> 0
B16: =IF(설정!$B$10="","",설정!$B$10) -> 용돈 / 기타 | C16: =IF(설정!$C$10="","",설정!$C$10) -> 0 | E16: =IF(D16="","",D16-C16) | L16: =IF(설정!$B$42="","",설정!$B$42) -> 여행 | M16: =IF(설정!$C$42="","",설정!$C$42) -> 100000 | N16: =SUMIF($H$5:$H$54,L16,$J$5:$J$54) -> 0 | O16: =IFERROR(N16/M16,0) -> 0 | P16: =IF(M16="","",REPT("■",MIN(10,ROUND(O16*10,0)))&REPT("□",10-MIN(10,ROUND(O16*10,0)))) -> □□□□□□□□□□ | V16: =IF(L19="","",L19) -> 기타 | W16: =N19 -> 0
B17: =IF(설정!$B$11="","",설정!$B$11) | C17: =IF(설정!$C$11="","",설정!$C$11) | E17: =IF(D17="","",D17-C17) | L17: =IF(설정!$B$43="","",설정!$B$43) -> 통신 / 디지털 | M17: =IF(설정!$C$43="","",설정!$C$43) -> 30000 | N17: =SUMIF($H$5:$H$54,L17,$J$5:$J$54) -> 0 | O17: =IFERROR(N17/M17,0) -> 0 | P17: =IF(M17="","",REPT("■",MIN(10,ROUND(O17*10,0)))&REPT("□",10-MIN(10,ROUND(O17*10,0)))) -> □□□□□□□□□□ | V17: =IF(B23="","",B23) -> 월세 / 주택대출 상환 | W17: =E23 -> 0
B18: =IF(설정!$B$12="","",설정!$B$12) | C18: =IF(설정!$C$12="","",설정!$C$12) | E18: =IF(D18="","",D18-C18) | L18: =IF(설정!$B$44="","",설정!$B$44) -> 기부 / 후원 | M18: =IF(설정!$C$44="","",설정!$C$44) -> 30000 | N18: =SUMIF($H$5:$H$54,L18,$J$5:$J$54) -> 0 | O18: =IFERROR(N18/M18,0) -> 0 | P18: =IF(M18="","",REPT("■",MIN(10,ROUND(O18*10,0)))&REPT("□",10-MIN(10,ROUND(O18*10,0)))) -> □□□□□□□□□□ | V18: =IF(B24="","",B24) -> 관리비 | W18: =E24 -> 0
B19: 합계 | C19: =SUM(C12:C18) -> 3950000 | D19: =SUM(D12:D18) -> 0 | E19: =D19-C19 -> -3950000 | L19: =IF(설정!$B$45="","",설정!$B$45) -> 기타 | M19: =IF(설정!$C$45="","",설정!$C$45) -> 80000 | N19: =SUMIF($H$5:$H$54,L19,$J$5:$J$54) -> 0 | O19: =IFERROR(N19/M19,0) -> 0 | P19: =IF(M19="","",REPT("■",MIN(10,ROUND(O19*10,0)))&REPT("□",10-MIN(10,ROUND(O19*10,0)))) -> □□□□□□□□□□ | V19: =IF(B25="","",B25) -> 통신비 (휴대폰·인터넷) | W19: =E25 -> 0
L20: 합계 | M20: =SUM(M5:M19) -> 1410000 | N20: =SUM(N5:N19) -> 0 | V20: =IF(B26="","",B26) -> 보험료 | W20: =E26 -> 0
B21: 고정지출 | V21: =IF(B27="","",B27) -> 구독 서비스 | W21: =E27 -> 0
B22: 항목 | C22: 예산 | D22: 결제일 | E22: 실제 | V22: =IF(B28="","",B28) -> 교통 정기권 | W22: =E28 -> 0
B23: =IF(설정!$B$16="","",설정!$B$16) -> 월세 / 주택대출 상환 | C23: =IF(설정!$C$16="","",설정!$C$16) -> 600000 | D23: =IF(설정!$D$16="","",설정!$D$16) -> 25일 | V23: =IF(B29="","",B29) -> 적금 | W23: =E29 -> 0
B24: =IF(설정!$B$17="","",설정!$B$17) -> 관리비 | C24: =IF(설정!$C$17="","",설정!$C$17) -> 150000 | D24: =IF(설정!$D$17="","",설정!$D$17) -> 30일 | V24: =IF(B30="","",B30) -> 청약저축 | W24: =E30 -> 0
B25: =IF(설정!$B$18="","",설정!$B$18) -> 통신비 (휴대폰·인터넷) | C25: =IF(설정!$C$18="","",설정!$C$18) -> 88000 | D25: =IF(설정!$D$18="","",설정!$D$18) -> 15일 | V25: =IF(B31="","",B31) -> 대출 이자 | W25: =E31 -> 0
B26: =IF(설정!$B$19="","",설정!$B$19) -> 보험료 | C26: =IF(설정!$C$19="","",설정!$C$19) -> 120000 | D26: =IF(설정!$D$19="","",설정!$D$19) -> 5일 | V26: =IF(B32="","",B32) -> 공과금 (전기·가스·수도) | W26: =E32 -> 0
B27: =IF(설정!$B$20="","",설정!$B$20) -> 구독 서비스 | C27: =IF(설정!$C$20="","",설정!$C$20) -> 29000 | D27: =IF(설정!$D$20="","",설정!$D$20) -> 10일 | V27: =IF(B33="","",B33) | W27: =E33 -> 0
B28: =IF(설정!$B$21="","",설정!$B$21) -> 교통 정기권 | C28: =IF(설정!$C$21="","",설정!$C$21) -> 62000 | D28: =IF(설정!$D$21="","",설정!$D$21) -> 1일 | V28: =IF(B34="","",B34) | W28: =E34 -> 0
B29: =IF(설정!$B$22="","",설정!$B$22) -> 적금 | C29: =IF(설정!$C$22="","",설정!$C$22) -> 300000 | D29: =IF(설정!$D$22="","",설정!$D$22) -> 25일
B30: =IF(설정!$B$23="","",설정!$B$23) -> 청약저축 | C30: =IF(설정!$C$23="","",설정!$C$23) -> 100000 | D30: =IF(설정!$D$23="","",설정!$D$23) -> 25일
B31: =IF(설정!$B$24="","",설정!$B$24) -> 대출 이자 | C31: =IF(설정!$C$24="","",설정!$C$24) -> 180000 | D31: =IF(설정!$D$24="","",설정!$D$24) -> 25일
B32: =IF(설정!$B$25="","",설정!$B$25) -> 공과금 (전기·가스·수도) | C32: =IF(설정!$C$25="","",설정!$C$25) -> 140000 | D32: =IF(설정!$D$25="","",설정!$D$25) -> 말일
B33: =IF(설정!$B$26="","",설정!$B$26) | C33: =IF(설정!$C$26="","",설정!$C$26) | D33: =IF(설정!$D$26="","",설정!$D$26)
B34: =IF(설정!$B$27="","",설정!$B$27) | C34: =IF(설정!$C$27="","",설정!$C$27) | D34: =IF(설정!$D$27="","",설정!$D$27)
B35: 합계 | C35: =SUM(C23:C34) -> 1769000 | E35: =SUM(E23:E34) -> 0
B37: 저축·투자
B38: 항목 | C38: 목표 | D38: 실제 | E38: 차이
B39: =IF(설정!$B$49="","",설정!$B$49) -> 비상금 | C39: =IF(설정!$C$49="","",설정!$C$49) -> 150000 | E39: =IF(D39="","",D39-C39)
B40: =IF(설정!$B$50="","",설정!$B$50) -> 청약 / 내집마련 | C40: =IF(설정!$C$50="","",설정!$C$50) -> 100000 | E40: =IF(D40="","",D40-C40)
B41: =IF(설정!$B$51="","",설정!$B$51) -> 투자 (ETF·주식) | C41: =IF(설정!$C$51="","",설정!$C$51) -> 400000 | E41: =IF(D41="","",D41-C41)
...

Sheet 6월
B1: 6월 가계부 | L1: 제이슨의 머니쇼 · 2026 | V1: 월 지출(전체) 차트 데이터
V2: =IF(L5="","",L5) -> 식비 (장보기) | W2: =N5 -> 0
B3: 이번 달 한눈에 | G3: 변동지출 기록 | L3: 카테고리별 예산 vs 사용 | R3: 차트 데이터 | V3: =IF(L6="","",L6) -> 외식 / 카페 | W3: =N6 -> 0
B4: 총수입 | D4: =D19 -> 0 | G4: 날짜 | H4: 분류 | I4: 내용 | J4: 금액 | L4: 분류 | M4: 예산 | N4: 사용 | O4: 달성 | P4: 진행 | R4: 구분 | S4: 예산 | T4: 실제 | V4: =IF(L7="","",L7) -> 생활용품 | W4: =N7 -> 0
B5: 총지출 | D5: =E35+J55 -> 0 | L5: =IF(설정!$B$31="","",설정!$B$31) -> 식비 (장보기) | M5: =IF(설정!$C$31="","",설정!$C$31) -> 350000 | N5: =SUMIF($H$5:$H$54,L5,$J$5:$J$54) -> 0 | O5: =IFERROR(N5/M5,0) -> 0 | P5: =IF(M5="","",REPT("■",MIN(10,ROUND(O5*10,0)))&REPT("□",10-MIN(10,ROUND(O5*10,0)))) -> □□□□□□□□□□ | R5: 수입 | S5: =C19 -> 3950000 | T5: =D19 -> 0 | V5: =IF(L8="","",L8) -> 교통 / 차량 | W5: =N8 -> 0
B6: 저축·투자 | D6: =D45 -> 0 | L6: =IF(설정!$B$32="","",설정!$B$32) -> 외식 / 카페 | M6: =IF(설정!$C$32="","",설정!$C$32) -> 200000 | N6: =SUMIF($H$5:$H$54,L6,$J$5:$J$54) -> 0 | O6: =IFERROR(N6/M6,0) -> 0 | P6: =IF(M6="","",REPT("■",MIN(10,ROUND(O6*10,0)))&REPT("□",10-MIN(10,ROUND(O6*10,0)))) -> □□□□□□□□□□ | R6: 지출 | S6: =C35+M20 -> 3179000 | T6: =E35+J55 -> 0 | V6: =IF(L9="","",L9) -> 의료 / 건강 | W6: =N9 -> 0
B7: 남은 돈 | D7: =D4-D5-D6 -> 0 | L7: =IF(설정!$B$33="","",설정!$B$33) -> 생활용품 | M7: =IF(설정!$C$33="","",설정!$C$33) -> 80000 | N7: =SUMIF($H$5:$H$54,L7,$J$5:$J$54) -> 0 | O7: =IFERROR(N7/M7,0) -> 0 | P7: =IF(M7="","",REPT("■",MIN(10,ROUND(O7*10,0)))&REPT("□",10-MIN(10,ROUND(O7*10,0)))) -> □□□□□□□□□□ | R7: 저축 | S7: =C45 -> 1100000 | T7: =D45 -> 0 | V7: =IF(L10="","",L10) -> 의류 / 미용 | W7: =N10 -> 0
B8: 저축률 | D8: =IFERROR((D4-D5)/D4,0) -> 0 | L8: =IF(설정!$B$34="","",설정!$B$34) -> 교통 / 차량 | M8: =IF(설정!$C$34="","",설정!$C$34) -> 120000 | N8: =SUMIF($H$5:$H$54,L8,$J$5:$J$54) -> 0 | O8: =IFERROR(N8/M8,0) -> 0 | P8: =IF(M8="","",REPT("■",MIN(10,ROUND(O8*10,0)))&REPT("□",10-MIN(10,ROUND(O8*10,0)))) -> □□□□□□□□□□ | V8: =IF(L11="","",L11) -> 교육 / 자기계발 | W8: =N11 -> 0
L9: =IF(설정!$B$35="","",설정!$B$35) -> 의료 / 건강 | M9: =IF(설정!$C$35="","",설정!$C$35) -> 60000 | N9: =SUMIF($H$5:$H$54,L9,$J$5:$J$54) -> 0 | O9: =IFERROR(N9/M9,0) -> 0 | P9: =IF(M9="","",REPT("■",MIN(10,ROUND(O9*10,0)))&REPT("□",10-MIN(10,ROUND(O9*10,0)))) -> □□□□□□□□□□ | R9: 고정지출 | S9: =E35 -> 0 | V9: =IF(L12="","",L12) -> 문화 / 여가 | W9: =N12 -> 0
B10: 수입 | L10: =IF(설정!$B$36="","",설정!$B$36) -> 의류 / 미용 | M10: =IF(설정!$C$36="","",설정!$C$36) -> 100000 | N10: =SUMIF($H$5:$H$54,L10,$J$5:$J$54) -> 0 | O10: =IFERROR(N10/M10,0) -> 0 | P10: =IF(M10="","",REPT("■",MIN(10,ROUND(O10*10,0)))&REPT("□",10-MIN(10,ROUND(O10*10,0)))) -> □□□□□□□□□□ | R10: 변동지출 | S10: =J55 -> 0 | V10: =IF(L13="","",L13) -> 경조사 / 선물 | W10: =N13 -> 0
B11: 항목 | C11: 예상 | D11: 실제 | E11: 차이 | L11: =IF(설정!$B$37="","",설정!$B$37) -> 교육 / 자기계발 | M11: =IF(설정!$C$37="","",설정!$C$37) -> 80000 | N11: =SUMIF($H$5:$H$54,L11,$J$5:$J$54) -> 0 | O11: =IFERROR(N11/M11,0) -> 0 | P11: =IF(M11="","",REPT("■",MIN(10,ROUND(O11*10,0)))&REPT("□",10-MIN(10,ROUND(O11*10,0)))) -> □□□□□□□□□□ | V11: =IF(L14="","",L14) -> 자녀 / 육아 | W11: =N14 -> 0
B12: =IF(설정!$B$6="","",설정!$B$6) -> 월급 (본업) | C12: =IF(설정!$C$6="","",설정!$C$6) -> 3500000 | E12: =IF(D12="","",D12-C12) | L12: =IF(설정!$B$38="","",설정!$B$38) -> 문화 / 여가 | M12: =IF(설정!$C$38="","",설정!$C$38) -> 80000 | N12: =SUMIF($H$5:$H$54,L12,$J$5:$J$54) -> 0 | O12: =IFERROR(N12/M12,0) -> 0 | P12: =IF(M12="","",REPT("■",MIN(10,ROUND(O12*10,0)))&REPT("□",10-MIN(10,ROUND(O12*10,0)))) -> □□□□□□□□□□ | V12: =IF(L15="","",L15) -> 반려동물 | W12: =N15 -> 0
B13: =IF(설정!$B$7="","",설정!$B$7) -> 부수입 / 사이드잡 | C13: =IF(설정!$C$7="","",설정!$C$7) -> 400000 | E13: =IF(D13="","",D13-C13) | L13: =IF(설정!$B$39="","",설정!$B$39) -> 경조사 / 선물 | M13: =IF(설정!$C$39="","",설정!$C$39) -> 100000 | N13: =SUMIF($H$5:$H$54,L13,$J$5:$J$54) -> 0 | O13: =IFERROR(N13/M13,0) -> 0 | P13: =IF(M13="","",REPT("■",MIN(10,ROUND(O13*10,0)))&REPT("□",10-MIN(10,ROUND(O13*10,0)))) -> □□□□□□□□□□ | V13: =IF(L16="","",L16) -> 여행 | W13: =N16 -> 0
B14: =IF(설정!$B$8="","",설정!$B$8) -> 상여 / 보너스 | C14: =IF(설정!$C$8="","",설정!$C$8) -> 0 | E14: =IF(D14="","",D14-C14) | L14: =IF(설정!$B$40="","",설정!$B$40) -> 자녀 / 육아 | M14: =IF(설정!$C$40="","",설정!$C$40) -> 0 | N14: =SUMIF($H$5:$H$54,L14,$J$5:$J$54) -> 0 | O14: =IFERROR(N14/M14,0) -> 0 | P14: =IF(M14="","",REPT("■",MIN(10,ROUND(O14*10,0)))&REPT("□",10-MIN(10,ROUND(O14*10,0)))) -> □□□□□□□□□□ | V14: =IF(L17="","",L17) -> 통신 / 디지털 | W14: =N17 -> 0
B15: =IF(설정!$B$9="","",설정!$B$9) -> 이자 / 배당 | C15: =IF(설정!$C$9="","",설정!$C$9) -> 50000 | E15: =IF(D15="","",D15-C15) | L15: =IF(설정!$B$41="","",설정!$B$41) -> 반려동물 | M15: =IF(설정!$C$41="","",설정!$C$41) -> 0 | N15: =SUMIF($H$5:$H$54,L15,$J$5:$J$54) -> 0 | O15: =IFERROR(N15/M15,0) -> 0 | P15: =IF(M15="","",REPT("■",MIN(10,ROUND(O15*10,0)))&REPT("□",10-MIN(10,ROUND(O15*10,0)))) -> □□□□□□□□□□ | V15: =IF(L18="","",L18) -> 기부 / 후원 | W15: =N18 -> 0
B16: =IF(설정!$B$10="","",설정!$B$10) -> 용돈 / 기타 | C16: =IF(설정!$C$10="","",설정!$C$10) -> 0 | E16: =IF(D16="","",D16-C16) | L16: =IF(설정!$B$42="","",설정!$B$42) -> 여행 | M16: =IF(설정!$C$42="","",설정!$C$42) -> 100000 | N16: =SUMIF($H$5:$H$54,L16,$J$5:$J$54) -> 0 | O16: =IFERROR(N16/M16,0) -> 0 | P16: =IF(M16="","",REPT("■",MIN(10,ROUND(O16*10,0)))&REPT("□",10-MIN(10,ROUND(O16*10,0)))) -> □□□□□□□□□□ | V16: =IF(L19="","",L19) -> 기타 | W16: =N19 -> 0
B17: =IF(설정!$B$11="","",설정!$B$11) | C17: =IF(설정!$C$11="","",설정!$C$11) | E17: =IF(D17="","",D17-C17) | L17: =IF(설정!$B$43="","",설정!$B$43) -> 통신 / 디지털 | M17: =IF(설정!$C$43="","",설정!$C$43) -> 30000 | N17: =SUMIF($H$5:$H$54,L17,$J$5:$J$54) -> 0 | O17: =IFERROR(N17/M17,0) -> 0 | P17: =IF(M17="","",REPT("■",MIN(10,ROUND(O17*10,0)))&REPT("□",10-MIN(10,ROUND(O17*10,0)))) -> □□□□□□□□□□ | V17: =IF(B23="","",B23) -> 월세 / 주택대출 상환 | W17: =E23 -> 0
B18: =IF(설정!$B$12="","",설정!$B$12) | C18: =IF(설정!$C$12="","",설정!$C$12) | E18: =IF(D18="","",D18-C18) | L18: =IF(설정!$B$44="","",설정!$B$44) -> 기부 / 후원 | M18: =IF(설정!$C$44="","",설정!$C$44) -> 30000 | N18: =SUMIF($H$5:$H$54,L18,$J$5:$J$54) -> 0 | O18: =IFERROR(N18/M18,0) -> 0 | P18: =IF(M18="","",REPT("■",MIN(10,ROUND(O18*10,0)))&REPT("□",10-MIN(10,ROUND(O18*10,0)))) -> □□□□□□□□□□ | V18: =IF(B24="","",B24) -> 관리비 | W18: =E24 -> 0
B19: 합계 | C19: =SUM(C12:C18) -> 3950000 | D19: =SUM(D12:D18) -> 0 | E19: =D19-C19 -> -3950000 | L19: =IF(설정!$B$45="","",설정!$B$45) -> 기타 | M19: =IF(설정!$C$45="","",설정!$C$45) -> 80000 | N19: =SUMIF($H$5:$H$54,L19,$J$5:$J$54) -> 0 | O19: =IFERROR(N19/M19,0) -> 0 | P19: =IF(M19="","",REPT("■",MIN(10,ROUND(O19*10,0)))&REPT("□",10-MIN(10,ROUND(O19*10,0)))) -> □□□□□□□□□□ | V19: =IF(B25="","",B25) -> 통신비 (휴대폰·인터넷) | W19: =E25 -> 0
L20: 합계 | M20: =SUM(M5:M19) -> 1410000 | N20: =SUM(N5:N19) -> 0 | V20: =IF(B26="","",B26) -> 보험료 | W20: =E26 -> 0
B21: 고정지출 | V21: =IF(B27="","",B27) -> 구독 서비스 | W21: =E27 -> 0
B22: 항목 | C22: 예산 | D22: 결제일 | E22: 실제 | V22: =IF(B28="","",B28) -> 교통 정기권 | W22: =E28 -> 0
B23: =IF(설정!$B$16="","",설정!$B$16) -> 월세 / 주택대출 상환 | C23: =IF(설정!$C$16="","",설정!$C$16) -> 600000 | D23: =IF(설정!$D$16="","",설정!$D$16) -> 25일 | V23: =IF(B29="","",B29) -> 적금 | W23: =E29 -> 0
B24: =IF(설정!$B$17="","",설정!$B$17) -> 관리비 | C24: =IF(설정!$C$17="","",설정!$C$17) -> 150000 | D24: =IF(설정!$D$17="","",설정!$D$17) -> 30일 | V24: =IF(B30="","",B30) -> 청약저축 | W24: =E30 -> 0
B25: =IF(설정!$B$18="","",설정!$B$18) -> 통신비 (휴대폰·인터넷) | C25: =IF(설정!$C$18="","",설정!$C$18) -> 88000 | D25: =IF(설정!$D$18="","",설정!$D$18) -> 15일 | V25: =IF(B31="","",B31) -> 대출 이자 | W25: =E31 -> 0
B26: =IF(설정!$B$19="","",설정!$B$19) -> 보험료 | C26: =IF(설정!$C$19="","",설정!$C$19) -> 120000 | D26: =IF(설정!$D$19="","",설정!$D$19) -> 5일 | V26: =IF(B32="","",B32) -> 공과금 (전기·가스·수도) | W26: =E32 -> 0
B27: =IF(설정!$B$20="","",설정!$B$20) -> 구독 서비스 | C27: =IF(설정!$C$20="","",설정!$C$20) -> 29000 | D27: =IF(설정!$D$20="","",설정!$D$20) -> 10일 | V27: =IF(B33="","",B33) | W27: =E33 -> 0
B28: =IF(설정!$B$21="","",설정!$B$21) -> 교통 정기권 | C28: =IF(설정!$C$21="","",설정!$C$21) -> 62000 | D28: =IF(설정!$D$21="","",설정!$D$21) -> 1일 | V28: =IF(B34="","",B34) | W28: =E34 -> 0
B29: =IF(설정!$B$22="","",설정!$B$22) -> 적금 | C29: =IF(설정!$C$22="","",설정!$C$22) -> 300000 | D29: =IF(설정!$D$22="","",설정!$D$22) -> 25일
B30: =IF(설정!$B$23="","",설정!$B$23) -> 청약저축 | C30: =IF(설정!$C$23="","",설정!$C$23) -> 100000 | D30: =IF(설정!$D$23="","",설정!$D$23) -> 25일
B31: =IF(설정!$B$24="","",설정!$B$24) -> 대출 이자 | C31: =IF(설정!$C$24="","",설정!$C$24) -> 180000 | D31: =IF(설정!$D$24="","",설정!$D$24) -> 25일
B32: =IF(설정!$B$25="","",설정!$B$25) -> 공과금 (전기·가스·수도) | C32: =IF(설정!$C$25="","",설정!$C$25) -> 140000 | D32: =IF(설정!$D$25="","",설정!$D$25) -> 말일
B33: =IF(설정!$B$26="","",설정!$B$26) | C33: =IF(설정!$C$26="","",설정!$C$26) | D33: =IF(설정!$D$26="","",설정!$D$26)
B34: =IF(설정!$B$27="","",설정!$B$27) | C34: =IF(설정!$C$27="","",설정!$C$27) | D34: =IF(설정!$D$27="","",설정!$D$27)
